[2019-12-17 10:34:38,566] {/home/alta-18/Documents/Alterra/FlaskPractice/app.py:25} WARNING - REQUEST_LOG	{"request": {}, "response": []}
[2019-12-17 10:34:58,986] {/home/alta-18/Documents/Alterra/FlaskPractice/app.py:25} WARNING - REQUEST_LOG	{"request": {}, "response": []}
[2019-12-17 10:35:00,356] {/home/alta-18/Documents/Alterra/FlaskPractice/app.py:25} WARNING - REQUEST_LOG	{"request": {}, "response": []}
[2019-12-17 10:35:02,148] {/home/alta-18/Documents/Alterra/FlaskPractice/app.py:25} WARNING - REQUEST_LOG	{"request": {}, "response": []}
[2019-12-17 10:35:22,055] {/home/alta-18/Documents/Alterra/FlaskPractice/app.py:25} WARNING - REQUEST_LOG	{"request": {}, "response": []}
[2019-12-17 10:35:23,930] {/home/alta-18/Documents/Alterra/FlaskPractice/app.py:25} WARNING - REQUEST_LOG	{"request": {}, "response": []}
[2019-12-17 10:35:30,654] {/home/alta-18/Documents/Alterra/FlaskPractice/app.py:25} WARNING - REQUEST_LOG	{"request": {}, "response": []}
[2019-12-17 10:35:31,698] {/home/alta-18/Documents/Alterra/FlaskPractice/app.py:25} WARNING - REQUEST_LOG	{"request": {}, "response": []}
[2019-12-17 10:35:32,593] {/home/alta-18/Documents/Alterra/FlaskPractice/app.py:25} WARNING - REQUEST_LOG	{"request": {}, "response": []}
[2019-12-17 10:35:33,404] {/home/alta-18/Documents/Alterra/FlaskPractice/app.py:25} WARNING - REQUEST_LOG	{"request": {}, "response": []}
[2019-12-17 10:35:34,310] {/home/alta-18/Documents/Alterra/FlaskPractice/app.py:25} WARNING - REQUEST_LOG	{"request": {}, "response": []}
[2019-12-17 10:35:41,075] {/home/alta-18/Documents/Alterra/FlaskPractice/app.py:25} WARNING - REQUEST_LOG	{"request": {}, "response": []}
[2019-12-17 10:35:41,995] {/home/alta-18/Documents/Alterra/FlaskPractice/app.py:25} WARNING - REQUEST_LOG	{"request": {}, "response": []}
[2019-12-17 10:35:42,848] {/home/alta-18/Documents/Alterra/FlaskPractice/app.py:25} WARNING - REQUEST_LOG	{"request": {}, "response": []}
[2019-12-17 10:36:01,300] {/home/alta-18/Documents/Alterra/FlaskPractice/app.py:25} WARNING - REQUEST_LOG	{"request": {}, "response": []}
[2019-12-17 10:36:06,429] {/home/alta-18/Documents/Alterra/FlaskPractice/app.py:25} WARNING - REQUEST_LOG	{"request": {}, "response": {"message": "NOT_FOUND"}}
[2019-12-17 10:36:15,412] {/home/alta-18/Documents/Alterra/FlaskPractice/app.py:25} WARNING - REQUEST_LOG	{"request": {}, "response": {"message": "NOT_FOUND"}}
[2019-12-17 10:37:09,909] {/home/alta-18/Documents/Alterra/FlaskPractice/app.py:25} WARNING - REQUEST_LOG	{"request": {}, "response": []}
[2019-12-17 10:38:16,672] {/home/alta-18/Documents/Alterra/FlaskPractice/app.py:25} WARNING - REQUEST_LOG	{"request": {}, "response": []}
[2019-12-17 10:44:00,025] {/home/alta-18/Documents/Alterra/FlaskPractice/app.py:25} WARNING - REQUEST_LOG	{"request": {}, "response": {"message": "The requested URL was not found on the server. If you entered the URL manually please check your spelling and try again."}}
[2019-12-17 10:44:10,108] {/home/alta-18/Documents/Alterra/FlaskPractice/app.py:25} WARNING - REQUEST_LOG	{"request": {}, "response": {"message": "The requested URL was not found on the server. If you entered the URL manually please check your spelling and try again."}}
[2019-12-17 10:44:44,424] {/home/alta-18/Documents/Alterra/FlaskPractice/app.py:30} WARNING - REQUEST_LOG	{"request": {"nama": "Wildan Firdaus", "age": 22, "sex": "Male", "client_id": 4}, "response": {"message": {"name": "Missing required parameter in the JSON body"}}}
[2019-12-17 10:49:04,557] {/home/alta-18/Documents/Alterra/FlaskPractice/app.py:31} WARNING - REQUEST_LOG	{"status_code": 400, "method": "POST", "code": "400 BAD REQUEST", "request": {"nama": "Wildan Firdaus", "age": 22, "sex": "Male", "client_id": 4}, "response": {"message": {"name": "Missing required parameter in the JSON body"}}}
[2019-12-17 10:49:30,357] {/home/alta-18/Documents/Alterra/FlaskPractice/app.py:31} WARNING - REQUEST_LOG	{"method": "POST", "code": "400 BAD REQUEST", "request": {"nama": "Wildan Firdaus", "age": 22, "sex": "Male", "client_id": 4}, "response": {"message": {"name": "Missing required parameter in the JSON body"}}}
[2019-12-17 10:50:39,434] {/home/alta-18/Documents/Alterra/FlaskPractice/app.py:31} WARNING - REQUEST_LOG	{"method": "POST", "code": "400 BAD REQUEST", "request": {}, "response": {"message": "Failed to decode JSON object: Expecting value: line 1 column 1 (char 0)"}}
[2019-12-17 10:51:50,931] {/home/alta-18/Documents/Alterra/FlaskPractice/app.py:31} WARNING - REQUEST_LOG	{"method": "GET", "code": "404 NOT FOUND", "request": {}, "response": {"message": "The requested URL was not found on the server. If you entered the URL manually please check your spelling and try again."}}
[2019-12-17 10:51:56,153] {/home/alta-18/Documents/Alterra/FlaskPractice/app.py:31} WARNING - REQUEST_LOG	{"method": "GET", "code": "200 OK", "request": {}, "response": []}
[2019-12-17 10:52:08,555] {/home/alta-18/Documents/Alterra/FlaskPractice/app.py:31} WARNING - REQUEST_LOG	{"method": "GET", "code": "200 OK", "request": {"nama": "Wildan Firdaus", "age": 22, "sex": "Male", "client_id": 4}, "response": []}
[2019-12-17 10:52:30,206] {/home/alta-18/Documents/Alterra/FlaskPractice/app.py:31} WARNING - REQUEST_LOG	{"method": "GET", "code": "200 OK", "request": {"name": "Wildan Firdaus", "age": 22, "sex": "Male", "client_id": 4}, "response": []}
[2019-12-17 10:52:42,066] {/home/alta-18/Documents/Alterra/FlaskPractice/app.py:30} WARNING - REQUEST_LOG	{"method": "GET", "code": "200 OK", "request": {"name": "Wildan Firdaus", "age": 22, "sex": "Male", "client_id": 4}, "response": []}
[2019-12-17 10:53:23,217] {/home/alta-18/Documents/Alterra/FlaskPractice/app.py:30} WARNING - REQUEST_LOG	{"method": "GET", "code": "404 NOT FOUND", "request": {"name": "Wildan Firdaus", "age": 22, "sex": "Male", "client_id": 4}, "response": {"message": "The requested URL was not found on the server. If you entered the URL manually please check your spelling and try again."}}
[2019-12-17 10:53:33,804] {/home/alta-18/Documents/Alterra/FlaskPractice/app.py:30} WARNING - REQUEST_LOG	{"method": "POST", "code": "400 BAD REQUEST", "request": {}, "response": {"message": "Failed to decode JSON object: Expecting value: line 1 column 1 (char 0)"}}
[2019-12-17 10:53:38,565] {/home/alta-18/Documents/Alterra/FlaskPractice/app.py:30} WARNING - REQUEST_LOG	{"method": "POST", "code": "400 BAD REQUEST", "request": {}, "response": {"message": "Failed to decode JSON object: Expecting value: line 1 column 1 (char 0)"}}
[2019-12-17 10:56:24,652] {/home/alta-18/Documents/Alterra/FlaskPractice/app.py:30} WARNING - REQUEST_LOG	{"method": "POST", "code": "400 BAD REQUEST", "request": {}, "response": {"message": "Failed to decode JSON object: Expecting value: line 1 column 1 (char 0)"}}
[2019-12-17 10:58:06,241] {/home/alta-18/Documents/Alterra/FlaskPractice/app.py:30} WARNING - REQUEST_LOG	{"method": "GET", "code": "200 OK", "request": {}, "response": []}
[2019-12-17 11:00:12,072] {/home/alta-18/Documents/Alterra/FlaskPractice/app.py:30} WARNING - REQUEST_LOG	{"method": "GET", "code": "200 OK", "request": {}, "response": []}
[2019-12-17 11:00:21,193] {/home/alta-18/Documents/Alterra/FlaskPractice/.flaskblog_venv/lib/python3.6/site-packages/flask/app.py:1891} ERROR - Exception on / [GET]
Traceback (most recent call last):
  File "/home/alta-18/Documents/Alterra/FlaskPractice/.flaskblog_venv/lib/python3.6/site-packages/flask/app.py", line 2446, in wsgi_app
    response = self.full_dispatch_request()
  File "/home/alta-18/Documents/Alterra/FlaskPractice/.flaskblog_venv/lib/python3.6/site-packages/flask/app.py", line 1952, in full_dispatch_request
    return self.finalize_request(rv)
  File "/home/alta-18/Documents/Alterra/FlaskPractice/.flaskblog_venv/lib/python3.6/site-packages/flask/app.py", line 1969, in finalize_request
    response = self.process_response(response)
  File "/home/alta-18/Documents/Alterra/FlaskPractice/.flaskblog_venv/lib/python3.6/site-packages/flask/app.py", line 2266, in process_response
    response = handler(response)
  File "/home/alta-18/Documents/Alterra/FlaskPractice/app.py", line 30, in after_request
    "response": json.loads(response.data.decode("utf-8"))
  File "/usr/lib/python3.6/json/__init__.py", line 354, in loads
    return _default_decoder.decode(s)
  File "/usr/lib/python3.6/json/decoder.py", line 339, in decode
    obj, end = self.raw_decode(s, idx=_w(s, 0).end())
  File "/usr/lib/python3.6/json/decoder.py", line 357, in raw_decode
    raise JSONDecodeError("Expecting value", s, err.value) from None
json.decoder.JSONDecodeError: Expecting value: line 1 column 1 (char 0)
[2019-12-17 11:00:21,196] {/home/alta-18/Documents/Alterra/FlaskPractice/.flaskblog_venv/lib/python3.6/site-packages/flask/app.py:1975} ERROR - Request finalizing failed with an error while handling an error
Traceback (most recent call last):
  File "/home/alta-18/Documents/Alterra/FlaskPractice/.flaskblog_venv/lib/python3.6/site-packages/flask/app.py", line 1969, in finalize_request
    response = self.process_response(response)
  File "/home/alta-18/Documents/Alterra/FlaskPractice/.flaskblog_venv/lib/python3.6/site-packages/flask/app.py", line 2266, in process_response
    response = handler(response)
  File "/home/alta-18/Documents/Alterra/FlaskPractice/app.py", line 30, in after_request
    "response": json.loads(response.data.decode("utf-8"))
  File "/usr/lib/python3.6/json/__init__.py", line 354, in loads
    return _default_decoder.decode(s)
  File "/usr/lib/python3.6/json/decoder.py", line 339, in decode
    obj, end = self.raw_decode(s, idx=_w(s, 0).end())
  File "/usr/lib/python3.6/json/decoder.py", line 357, in raw_decode
    raise JSONDecodeError("Expecting value", s, err.value) from None
json.decoder.JSONDecodeError: Expecting value: line 1 column 1 (char 0)
[2019-12-17 11:00:58,462] {/home/alta-18/Documents/Alterra/FlaskPractice/.flaskblog_venv/lib/python3.6/site-packages/flask/app.py:1891} ERROR - Exception on / [GET]
Traceback (most recent call last):
  File "/home/alta-18/Documents/Alterra/FlaskPractice/.flaskblog_venv/lib/python3.6/site-packages/flask/app.py", line 2446, in wsgi_app
    response = self.full_dispatch_request()
  File "/home/alta-18/Documents/Alterra/FlaskPractice/.flaskblog_venv/lib/python3.6/site-packages/flask/app.py", line 1952, in full_dispatch_request
    return self.finalize_request(rv)
  File "/home/alta-18/Documents/Alterra/FlaskPractice/.flaskblog_venv/lib/python3.6/site-packages/flask/app.py", line 1969, in finalize_request
    response = self.process_response(response)
  File "/home/alta-18/Documents/Alterra/FlaskPractice/.flaskblog_venv/lib/python3.6/site-packages/flask/app.py", line 2266, in process_response
    response = handler(response)
  File "/home/alta-18/Documents/Alterra/FlaskPractice/app.py", line 30, in after_request
    "response": json.loads(response.data.decode("utf-8"))
  File "/usr/lib/python3.6/json/__init__.py", line 354, in loads
    return _default_decoder.decode(s)
  File "/usr/lib/python3.6/json/decoder.py", line 339, in decode
    obj, end = self.raw_decode(s, idx=_w(s, 0).end())
  File "/usr/lib/python3.6/json/decoder.py", line 357, in raw_decode
    raise JSONDecodeError("Expecting value", s, err.value) from None
json.decoder.JSONDecodeError: Expecting value: line 1 column 1 (char 0)
[2019-12-17 11:00:58,464] {/home/alta-18/Documents/Alterra/FlaskPractice/.flaskblog_venv/lib/python3.6/site-packages/flask/app.py:1975} ERROR - Request finalizing failed with an error while handling an error
Traceback (most recent call last):
  File "/home/alta-18/Documents/Alterra/FlaskPractice/.flaskblog_venv/lib/python3.6/site-packages/flask/app.py", line 1969, in finalize_request
    response = self.process_response(response)
  File "/home/alta-18/Documents/Alterra/FlaskPractice/.flaskblog_venv/lib/python3.6/site-packages/flask/app.py", line 2266, in process_response
    response = handler(response)
  File "/home/alta-18/Documents/Alterra/FlaskPractice/app.py", line 30, in after_request
    "response": json.loads(response.data.decode("utf-8"))
  File "/usr/lib/python3.6/json/__init__.py", line 354, in loads
    return _default_decoder.decode(s)
  File "/usr/lib/python3.6/json/decoder.py", line 339, in decode
    obj, end = self.raw_decode(s, idx=_w(s, 0).end())
  File "/usr/lib/python3.6/json/decoder.py", line 357, in raw_decode
    raise JSONDecodeError("Expecting value", s, err.value) from None
json.decoder.JSONDecodeError: Expecting value: line 1 column 1 (char 0)
[2019-12-17 11:01:22,166] {/home/alta-18/Documents/Alterra/FlaskPractice/app.py:30} WARNING - REQUEST_LOG	{"method": "GET", "code": "200 OK", "request": {}, "response": []}
[2019-12-17 11:01:31,489] {/home/alta-18/Documents/Alterra/FlaskPractice/app.py:30} WARNING - REQUEST_LOG	{"method": "GET", "code": "200 OK", "request": {}, "response": []}
[2019-12-17 11:05:33,876] {/home/alta-18/Documents/Alterra/FlaskPractice/app.py:30} WARNING - REQUEST_LOG	{"method": "GET", "code": "200 OK", "request": {}, "response": []}
[2019-12-17 11:07:06,816] {/home/alta-18/Documents/Alterra/FlaskPractice/app.py:30} WARNING - REQUEST_LOG	{"method": "GET", "code": "200 OK", "request": {}, "response": []}
[2019-12-17 11:07:16,219] {/home/alta-18/Documents/Alterra/FlaskPractice/app.py:30} WARNING - REQUEST_LOG	{"method": "GET", "code": "200 OK", "request": {}, "response": []}
[2019-12-17 11:07:30,397] {/home/alta-18/Documents/Alterra/FlaskPractice/app.py:30} INFO - REQUEST_LOG	{"method": "GET", "code": "200 OK", "request": {}, "response": []}
[2019-12-17 11:07:43,259] {/home/alta-18/Documents/Alterra/FlaskPractice/app.py:30} INFO - REQUEST_LOG	{"method": "GET", "code": "200 OK", "request": {}, "response": []}
[2019-12-17 11:07:51,149] {/home/alta-18/Documents/Alterra/FlaskPractice/app.py:30} INFO - REQUEST_LOG	{"method": "GET", "code": "200 OK", "request": {"name": "Wildan Firdaus", "age": 22, "sex": "Male", "client_id": 4}, "response": []}
[2019-12-17 11:08:31,129] {/home/alta-18/Documents/Alterra/FlaskPractice/app.py:30} INFO - REQUEST_LOG	{"method": "POST", "code": "200 OK", "request": {"name": "Wildan Firdaus", "age": 22, "sex": "Male", "client_id": 4}, "response": {"name": "Wildan Firdaus", "age": 22, "sex": "Male", "client_id": 4, "created_at": "2019-12-17, 11:08:31", "updated_at": "2019-12-17, 11:08:31", "id": 1}}
[2019-12-17 11:08:41,223] {/home/alta-18/Documents/Alterra/FlaskPractice/app.py:30} INFO - REQUEST_LOG	{"method": "POST", "code": "400 BAD REQUEST", "request": {}, "response": {"message": "Failed to decode JSON object: Expecting value: line 1 column 1 (char 0)"}}
[2019-12-17 11:10:33,514] {/home/alta-18/Documents/Alterra/FlaskPractice/app.py:30} INFO - REQUEST_LOG	{"method": "POST", "code": "400 BAD REQUEST", "request": {}, "response": {"message": "Failed to decode JSON object: Expecting value: line 1 column 1 (char 0)"}}
[2019-12-17 11:10:39,290] {/home/alta-18/Documents/Alterra/FlaskPractice/app.py:30} INFO - REQUEST_LOG	{"method": "POST", "code": "400 BAD REQUEST", "request": {}, "response": {"message": "Failed to decode JSON object: Expecting value: line 1 column 1 (char 0)"}}
[2019-12-17 11:10:44,286] {/home/alta-18/Documents/Alterra/FlaskPractice/app.py:30} INFO - REQUEST_LOG	{"method": "GET", "code": "200 OK", "request": {}, "response": []}
[2019-12-17 11:13:20,505] {/home/alta-18/Documents/Alterra/FlaskPractice/app.py:30} INFO - REQUEST_LOG	{"method": "GET", "code": "200 OK", "request": {}, "response": []}
[2019-12-17 11:13:27,013] {/home/alta-18/Documents/Alterra/FlaskPractice/app.py:30} INFO - REQUEST_LOG	{"method": "GET", "code": "200 OK", "request": {}, "response": []}
[2019-12-17 11:13:40,110] {/home/alta-18/Documents/Alterra/FlaskPractice/app.py:30} INFO - REQUEST_LOG	{"method": "GET", "code": "404 NOT FOUND", "request": {}, "response": {"message": "The requested URL was not found on the server. If you entered the URL manually please check your spelling and try again."}}
[2019-12-17 11:13:56,437] {/home/alta-18/Documents/Alterra/FlaskPractice/app.py:30} INFO - REQUEST_LOG	{"method": "GET", "code": "200 OK", "request": {}, "response": []}
[2019-12-17 11:17:17,790] {/home/alta-18/Documents/Alterra/FlaskPractice/app.py:31} INFO - REQUEST_LOG	{"method": "GET", "code": "200 OK", "request": {}, "response": []}
[2019-12-17 11:17:26,614] {/home/alta-18/Documents/Alterra/FlaskPractice/app.py:38} ERROR - REQUEST_LOG	{"method": "GET", "code": "404 NOT FOUND", "request": {}, "response": {"message": "The requested URL was not found on the server. If you entered the URL manually please check your spelling and try again."}}
[2019-12-17 11:17:38,007] {/home/alta-18/Documents/Alterra/FlaskPractice/app.py:38} ERROR - REQUEST_LOG	{"method": "GET", "code": "404 NOT FOUND", "request": {}, "response": {"message": "NOT_FOUND"}}
[2019-12-17 11:17:54,794] {/home/alta-18/Documents/Alterra/FlaskPractice/app.py:38} ERROR - REQUEST_LOG	{"method": "POST", "code": "400 BAD REQUEST", "request": {}, "response": {"message": "Failed to decode JSON object: Expecting value: line 1 column 1 (char 0)"}}
[2019-12-17 11:18:04,721] {/home/alta-18/Documents/Alterra/FlaskPractice/app.py:31} INFO - REQUEST_LOG	{"method": "POST", "code": "200 OK", "request": {"name": "Wildan Firdaus", "age": 22, "sex": "Male", "client_id": 4}, "response": {"name": "Wildan Firdaus", "age": 22, "sex": "Male", "client_id": 4, "created_at": "2019-12-17, 11:18:04", "updated_at": "2019-12-17, 11:18:04", "id": 1}}
[2019-12-17 11:18:20,038] {/home/alta-18/Documents/Alterra/FlaskPractice/app.py:38} ERROR - REQUEST_LOG	{"method": "POST", "code": "400 BAD REQUEST", "request": {"nama": "Wildan Firdaus", "age": 22, "sex": "Male", "client_id": 4}, "response": {"message": {"name": "Missing required parameter in the JSON body"}}}
[2019-12-17 11:18:39,637] {/home/alta-18/Documents/Alterra/FlaskPractice/app.py:31} INFO - REQUEST_LOG	{"method": "POST", "code": "200 OK", "request": {"name": "Wildan Firdaus", "age": 22, "sex": "Male", "client_id": 4}, "response": {"name": "Wildan Firdaus", "age": 22, "sex": "Male", "client_id": 4, "created_at": "2019-12-17, 11:18:39", "updated_at": "2019-12-17, 11:18:39", "id": 2}}
[2019-12-17 11:18:49,400] {/home/alta-18/Documents/Alterra/FlaskPractice/app.py:31} INFO - REQUEST_LOG	{"method": "GET", "code": "200 OK", "request": {"name": "Wildan Firdaus", "age": 22, "sex": "Male", "client_id": 4}, "response": [{"name": "Wildan Firdaus", "age": 22, "sex": "Male", "client_id": 4, "created_at": "2019-12-17, 11:18:04", "updated_at": "2019-12-17, 11:18:04", "id": 1}, {"name": "Wildan Firdaus", "age": 22, "sex": "Male", "client_id": 4, "created_at": "2019-12-17, 11:18:39", "updated_at": "2019-12-17, 11:18:39", "id": 2}]}
[2019-12-17 11:19:03,948] {/home/alta-18/Documents/Alterra/FlaskPractice/app.py:38} ERROR - REQUEST_LOG	{"method": "PUT", "code": "404 NOT FOUND", "request": {"name": "Wildan Firdaus", "age": 22, "sex": "Male", "client_id": 4}, "response": {"message": "NOT_FOUND"}}
[2019-12-17 11:19:35,712] {/home/alta-18/Documents/Alterra/FlaskPractice/app.py:31} INFO - REQUEST_LOG	{"method": "PUT", "code": "200 OK", "request": {"name": "Wildan", "age": 22, "sex": "Male", "client_id": 4}, "response": {"name": "Wildan", "age": 22, "sex": "Male", "client_id": 4, "created_at": "2019-12-17, 11:18:04", "updated_at": "2019-12-17, 11:19:35", "id": 1}}
[2019-12-17 11:19:48,677] {/home/alta-18/Documents/Alterra/FlaskPractice/app.py:38} ERROR - REQUEST_LOG	{"method": "PUT", "code": "404 NOT FOUND", "request": {"name": "Wildan", "age": 22, "sex": "Male", "client_id": 4}, "response": {"message": "NOT_FOUND"}}
[2019-12-17 11:19:54,341] {/home/alta-18/Documents/Alterra/FlaskPractice/app.py:31} INFO - REQUEST_LOG	{"method": "GET", "code": "200 OK", "request": {"name": "Wildan", "age": 22, "sex": "Male", "client_id": 4}, "response": [{"name": "Wildan", "age": 22, "sex": "Male", "client_id": 4, "created_at": "2019-12-17, 11:18:04", "updated_at": "2019-12-17, 11:19:35", "id": 1}, {"name": "Wildan Firdaus", "age": 22, "sex": "Male", "client_id": 4, "created_at": "2019-12-17, 11:18:39", "updated_at": "2019-12-17, 11:18:39", "id": 2}]}
[2019-12-17 17:01:27,070] {/home/alta-18/Documents/Alterra/FlaskPractice/blueprints/__init__.py:36} INFO - REQUEST_LOG	{"method": "GET", "code": "200 OK", "request": {"name": "Wildan", "age": 22, "sex": "Male", "client_id": 4}, "response": []}
[2019-12-17 17:01:38,053] {/home/alta-18/Documents/Alterra/FlaskPractice/blueprints/__init__.py:36} INFO - REQUEST_LOG	{"method": "GET", "code": "200 OK", "request": {}, "response": []}
[2019-12-17 17:02:52,214] {/home/alta-18/Documents/Alterra/FlaskPractice/blueprints/__init__.py:36} INFO - REQUEST_LOG	{"method": "GET", "code": "200 OK", "request": {"p": "1", "rp": "25", "orderby": "sex", "sort": "desc"}, "response": []}
[2019-12-17 17:05:21,037] {/home/alta-18/Documents/Alterra/FlaskPractice/blueprints/__init__.py:36} INFO - REQUEST_LOG	{"method": "GET", "code": "200 OK", "request": {"p": "1", "rp": "25", "orderby": "sex", "sort": "desc"}, "response": []}
[2019-12-17 17:05:47,871] {/home/alta-18/Documents/Alterra/FlaskPractice/.flaskblog_venv/lib/python3.6/site-packages/flask/app.py:1891} ERROR - Exception on /user [GET]
Traceback (most recent call last):
  File "/home/alta-18/Documents/Alterra/FlaskPractice/.flaskblog_venv/lib/python3.6/site-packages/sqlalchemy/engine/base.py", line 1246, in _execute_context
    cursor, statement, parameters, context
  File "/home/alta-18/Documents/Alterra/FlaskPractice/.flaskblog_venv/lib/python3.6/site-packages/sqlalchemy/engine/default.py", line 581, in do_execute
    cursor.execute(statement, parameters)
  File "/home/alta-18/Documents/Alterra/FlaskPractice/.flaskblog_venv/lib/python3.6/site-packages/pymysql/cursors.py", line 170, in execute
    result = self._query(query)
  File "/home/alta-18/Documents/Alterra/FlaskPractice/.flaskblog_venv/lib/python3.6/site-packages/pymysql/cursors.py", line 328, in _query
    conn.query(q)
  File "/home/alta-18/Documents/Alterra/FlaskPractice/.flaskblog_venv/lib/python3.6/site-packages/pymysql/connections.py", line 517, in query
    self._affected_rows = self._read_query_result(unbuffered=unbuffered)
  File "/home/alta-18/Documents/Alterra/FlaskPractice/.flaskblog_venv/lib/python3.6/site-packages/pymysql/connections.py", line 732, in _read_query_result
    result.read()
  File "/home/alta-18/Documents/Alterra/FlaskPractice/.flaskblog_venv/lib/python3.6/site-packages/pymysql/connections.py", line 1075, in read
    first_packet = self.connection._read_packet()
  File "/home/alta-18/Documents/Alterra/FlaskPractice/.flaskblog_venv/lib/python3.6/site-packages/pymysql/connections.py", line 684, in _read_packet
    packet.check_error()
  File "/home/alta-18/Documents/Alterra/FlaskPractice/.flaskblog_venv/lib/python3.6/site-packages/pymysql/protocol.py", line 220, in check_error
    err.raise_mysql_exception(self._data)
  File "/home/alta-18/Documents/Alterra/FlaskPractice/.flaskblog_venv/lib/python3.6/site-packages/pymysql/err.py", line 109, in raise_mysql_exception
    raise errorclass(errno, errval)
pymysql.err.ProgrammingError: (1064, "You have an error in your SQL syntax; check the manual that corresponds to your MySQL server version for the right syntax to use near '-25, 25' at line 3")

The above exception was the direct cause of the following exception:

Traceback (most recent call last):
  File "/home/alta-18/Documents/Alterra/FlaskPractice/.flaskblog_venv/lib/python3.6/site-packages/flask/app.py", line 1949, in full_dispatch_request
    rv = self.dispatch_request()
  File "/home/alta-18/Documents/Alterra/FlaskPractice/.flaskblog_venv/lib/python3.6/site-packages/flask/app.py", line 1935, in dispatch_request
    return self.view_functions[rule.endpoint](**req.view_args)
  File "/home/alta-18/Documents/Alterra/FlaskPractice/.flaskblog_venv/lib/python3.6/site-packages/flask_restful/__init__.py", line 458, in wrapper
    resp = resource(*args, **kwargs)
  File "/home/alta-18/Documents/Alterra/FlaskPractice/.flaskblog_venv/lib/python3.6/site-packages/flask/views.py", line 89, in view
    return self.dispatch_request(*args, **kwargs)
  File "/home/alta-18/Documents/Alterra/FlaskPractice/.flaskblog_venv/lib/python3.6/site-packages/flask_restful/__init__.py", line 573, in dispatch_request
    resp = meth(*args, **kwargs)
  File "/home/alta-18/Documents/Alterra/FlaskPractice/blueprints/user/resources.py", line 33, in get
    for row in qry.all():
  File "/home/alta-18/Documents/Alterra/FlaskPractice/.flaskblog_venv/lib/python3.6/site-packages/sqlalchemy/orm/query.py", line 3211, in all
    return list(self)
  File "/home/alta-18/Documents/Alterra/FlaskPractice/.flaskblog_venv/lib/python3.6/site-packages/sqlalchemy/orm/query.py", line 3367, in __iter__
    return self._execute_and_instances(context)
  File "/home/alta-18/Documents/Alterra/FlaskPractice/.flaskblog_venv/lib/python3.6/site-packages/sqlalchemy/orm/query.py", line 3392, in _execute_and_instances
    result = conn.execute(querycontext.statement, self._params)
  File "/home/alta-18/Documents/Alterra/FlaskPractice/.flaskblog_venv/lib/python3.6/site-packages/sqlalchemy/engine/base.py", line 982, in execute
    return meth(self, multiparams, params)
  File "/home/alta-18/Documents/Alterra/FlaskPractice/.flaskblog_venv/lib/python3.6/site-packages/sqlalchemy/sql/elements.py", line 287, in _execute_on_connection
    return connection._execute_clauseelement(self, multiparams, params)
  File "/home/alta-18/Documents/Alterra/FlaskPractice/.flaskblog_venv/lib/python3.6/site-packages/sqlalchemy/engine/base.py", line 1101, in _execute_clauseelement
    distilled_params,
  File "/home/alta-18/Documents/Alterra/FlaskPractice/.flaskblog_venv/lib/python3.6/site-packages/sqlalchemy/engine/base.py", line 1250, in _execute_context
    e, statement, parameters, cursor, context
  File "/home/alta-18/Documents/Alterra/FlaskPractice/.flaskblog_venv/lib/python3.6/site-packages/sqlalchemy/engine/base.py", line 1476, in _handle_dbapi_exception
    util.raise_from_cause(sqlalchemy_exception, exc_info)
  File "/home/alta-18/Documents/Alterra/FlaskPractice/.flaskblog_venv/lib/python3.6/site-packages/sqlalchemy/util/compat.py", line 398, in raise_from_cause
    reraise(type(exception), exception, tb=exc_tb, cause=cause)
  File "/home/alta-18/Documents/Alterra/FlaskPractice/.flaskblog_venv/lib/python3.6/site-packages/sqlalchemy/util/compat.py", line 152, in reraise
    raise value.with_traceback(tb)
  File "/home/alta-18/Documents/Alterra/FlaskPractice/.flaskblog_venv/lib/python3.6/site-packages/sqlalchemy/engine/base.py", line 1246, in _execute_context
    cursor, statement, parameters, context
  File "/home/alta-18/Documents/Alterra/FlaskPractice/.flaskblog_venv/lib/python3.6/site-packages/sqlalchemy/engine/default.py", line 581, in do_execute
    cursor.execute(statement, parameters)
  File "/home/alta-18/Documents/Alterra/FlaskPractice/.flaskblog_venv/lib/python3.6/site-packages/pymysql/cursors.py", line 170, in execute
    result = self._query(query)
  File "/home/alta-18/Documents/Alterra/FlaskPractice/.flaskblog_venv/lib/python3.6/site-packages/pymysql/cursors.py", line 328, in _query
    conn.query(q)
  File "/home/alta-18/Documents/Alterra/FlaskPractice/.flaskblog_venv/lib/python3.6/site-packages/pymysql/connections.py", line 517, in query
    self._affected_rows = self._read_query_result(unbuffered=unbuffered)
  File "/home/alta-18/Documents/Alterra/FlaskPractice/.flaskblog_venv/lib/python3.6/site-packages/pymysql/connections.py", line 732, in _read_query_result
    result.read()
  File "/home/alta-18/Documents/Alterra/FlaskPractice/.flaskblog_venv/lib/python3.6/site-packages/pymysql/connections.py", line 1075, in read
    first_packet = self.connection._read_packet()
  File "/home/alta-18/Documents/Alterra/FlaskPractice/.flaskblog_venv/lib/python3.6/site-packages/pymysql/connections.py", line 684, in _read_packet
    packet.check_error()
  File "/home/alta-18/Documents/Alterra/FlaskPractice/.flaskblog_venv/lib/python3.6/site-packages/pymysql/protocol.py", line 220, in check_error
    err.raise_mysql_exception(self._data)
  File "/home/alta-18/Documents/Alterra/FlaskPractice/.flaskblog_venv/lib/python3.6/site-packages/pymysql/err.py", line 109, in raise_mysql_exception
    raise errorclass(errno, errval)
sqlalchemy.exc.ProgrammingError: (pymysql.err.ProgrammingError) (1064, "You have an error in your SQL syntax; check the manual that corresponds to your MySQL server version for the right syntax to use near '-25, 25' at line 3")
[SQL: SELECT users.id AS users_id, users.name AS users_name, users.age AS users_age, users.sex AS users_sex, users.created_at AS users_created_at, users.updated_at AS users_updated_at 
FROM users ORDER BY users.sex DESC 
 LIMIT %(param_1)s, %(param_2)s]
[parameters: {'param_1': -25, 'param_2': 25}]
(Background on this error at: http://sqlalche.me/e/f405)
[2019-12-17 17:05:47,880] {/home/alta-18/Documents/Alterra/FlaskPractice/blueprints/__init__.py:43} ERROR - REQUEST_LOG	{"method": "GET", "code": "500 INTERNAL SERVER ERROR", "request": {"p": "0", "rp": "25", "orderby": "sex", "sort": "desc"}, "response": {"message": "Internal Server Error"}}
[2019-12-17 17:06:04,922] {/home/alta-18/Documents/Alterra/FlaskPractice/blueprints/__init__.py:36} INFO - REQUEST_LOG	{"method": "GET", "code": "200 OK", "request": {"p": "1", "rp": "25", "orderby": "sex", "sort": "desc"}, "response": []}
[2019-12-17 17:22:32,805] {/home/alta-18/Documents/Alterra/FlaskPractice/blueprints/__init__.py:36} INFO - REQUEST_LOG	{"method": "GET", "code": "200 OK", "request": {"p": "1", "rp": "25", "orderby": "sex", "sort": "desc"}, "response": []}
[2019-12-17 17:22:47,189] {/home/alta-18/Documents/Alterra/FlaskPractice/blueprints/__init__.py:36} INFO - REQUEST_LOG	{"method": "GET", "code": "200 OK", "request": {}, "response": []}
[2019-12-17 17:23:29,409] {/home/alta-18/Documents/Alterra/FlaskPractice/.flaskblog_venv/lib/python3.6/site-packages/flask/app.py:1891} ERROR - Exception on /user/2 [GET]
Traceback (most recent call last):
  File "/home/alta-18/Documents/Alterra/FlaskPractice/.flaskblog_venv/lib/python3.6/site-packages/flask/app.py", line 1949, in full_dispatch_request
    rv = self.dispatch_request()
  File "/home/alta-18/Documents/Alterra/FlaskPractice/.flaskblog_venv/lib/python3.6/site-packages/flask/app.py", line 1935, in dispatch_request
    return self.view_functions[rule.endpoint](**req.view_args)
  File "/home/alta-18/Documents/Alterra/FlaskPractice/.flaskblog_venv/lib/python3.6/site-packages/flask_restful/__init__.py", line 458, in wrapper
    resp = resource(*args, **kwargs)
  File "/home/alta-18/Documents/Alterra/FlaskPractice/.flaskblog_venv/lib/python3.6/site-packages/flask/views.py", line 89, in view
    return self.dispatch_request(*args, **kwargs)
  File "/home/alta-18/Documents/Alterra/FlaskPractice/.flaskblog_venv/lib/python3.6/site-packages/flask_restful/__init__.py", line 573, in dispatch_request
    resp = meth(*args, **kwargs)
  File "/home/alta-18/Documents/Alterra/FlaskPractice/blueprints/user/resources.py", line 38, in get
    for row in qry.all():
AttributeError: 'NoneType' object has no attribute 'all'
[2019-12-17 17:23:29,412] {/home/alta-18/Documents/Alterra/FlaskPractice/blueprints/__init__.py:43} ERROR - REQUEST_LOG	{"method": "GET", "code": "500 INTERNAL SERVER ERROR", "request": {}, "response": {"message": "Internal Server Error"}}
[2019-12-17 17:26:05,283] {/home/alta-18/Documents/Alterra/FlaskPractice/blueprints/__init__.py:43} ERROR - REQUEST_LOG	{"method": "GET", "code": "404 NOT FOUND", "request": {}, "response": {"message": "NOT_FOUND"}}
[2019-12-17 17:26:31,428] {/home/alta-18/Documents/Alterra/FlaskPractice/blueprints/__init__.py:43} ERROR - REQUEST_LOG	{"method": "GET", "code": "404 NOT FOUND", "request": {}, "response": {"message": "The requested URL was not found on the server. If you entered the URL manually please check your spelling and try again."}}
[2019-12-17 17:26:34,799] {/home/alta-18/Documents/Alterra/FlaskPractice/blueprints/__init__.py:36} INFO - REQUEST_LOG	{"method": "GET", "code": "200 OK", "request": {}, "response": []}
[2019-12-17 17:36:06,375] {/home/alta-18/Documents/Alterra/FlaskPractice/.flaskblog_venv/lib/python3.6/site-packages/flask/app.py:1891} ERROR - Exception on /user [POST]
Traceback (most recent call last):
  File "/home/alta-18/Documents/Alterra/FlaskPractice/.flaskblog_venv/lib/python3.6/site-packages/sqlalchemy/engine/base.py", line 1246, in _execute_context
    cursor, statement, parameters, context
  File "/home/alta-18/Documents/Alterra/FlaskPractice/.flaskblog_venv/lib/python3.6/site-packages/sqlalchemy/engine/default.py", line 581, in do_execute
    cursor.execute(statement, parameters)
  File "/home/alta-18/Documents/Alterra/FlaskPractice/.flaskblog_venv/lib/python3.6/site-packages/pymysql/cursors.py", line 170, in execute
    result = self._query(query)
  File "/home/alta-18/Documents/Alterra/FlaskPractice/.flaskblog_venv/lib/python3.6/site-packages/pymysql/cursors.py", line 328, in _query
    conn.query(q)
  File "/home/alta-18/Documents/Alterra/FlaskPractice/.flaskblog_venv/lib/python3.6/site-packages/pymysql/connections.py", line 517, in query
    self._affected_rows = self._read_query_result(unbuffered=unbuffered)
  File "/home/alta-18/Documents/Alterra/FlaskPractice/.flaskblog_venv/lib/python3.6/site-packages/pymysql/connections.py", line 732, in _read_query_result
    result.read()
  File "/home/alta-18/Documents/Alterra/FlaskPractice/.flaskblog_venv/lib/python3.6/site-packages/pymysql/connections.py", line 1075, in read
    first_packet = self.connection._read_packet()
  File "/home/alta-18/Documents/Alterra/FlaskPractice/.flaskblog_venv/lib/python3.6/site-packages/pymysql/connections.py", line 684, in _read_packet
    packet.check_error()
  File "/home/alta-18/Documents/Alterra/FlaskPractice/.flaskblog_venv/lib/python3.6/site-packages/pymysql/protocol.py", line 220, in check_error
    err.raise_mysql_exception(self._data)
  File "/home/alta-18/Documents/Alterra/FlaskPractice/.flaskblog_venv/lib/python3.6/site-packages/pymysql/err.py", line 109, in raise_mysql_exception
    raise errorclass(errno, errval)
pymysql.err.IntegrityError: (1048, "Column 'updated_at' cannot be null")

The above exception was the direct cause of the following exception:

Traceback (most recent call last):
  File "/home/alta-18/Documents/Alterra/FlaskPractice/.flaskblog_venv/lib/python3.6/site-packages/flask/app.py", line 1949, in full_dispatch_request
    rv = self.dispatch_request()
  File "/home/alta-18/Documents/Alterra/FlaskPractice/.flaskblog_venv/lib/python3.6/site-packages/flask/app.py", line 1935, in dispatch_request
    return self.view_functions[rule.endpoint](**req.view_args)
  File "/home/alta-18/Documents/Alterra/FlaskPractice/.flaskblog_venv/lib/python3.6/site-packages/flask_restful/__init__.py", line 458, in wrapper
    resp = resource(*args, **kwargs)
  File "/home/alta-18/Documents/Alterra/FlaskPractice/.flaskblog_venv/lib/python3.6/site-packages/flask/views.py", line 89, in view
    return self.dispatch_request(*args, **kwargs)
  File "/home/alta-18/Documents/Alterra/FlaskPractice/.flaskblog_venv/lib/python3.6/site-packages/flask_restful/__init__.py", line 573, in dispatch_request
    resp = meth(*args, **kwargs)
  File "/home/alta-18/Documents/Alterra/FlaskPractice/blueprints/user/resources.py", line 54, in post
    db.session.commit()
  File "/home/alta-18/Documents/Alterra/FlaskPractice/.flaskblog_venv/lib/python3.6/site-packages/sqlalchemy/orm/scoping.py", line 162, in do
    return getattr(self.registry(), name)(*args, **kwargs)
  File "/home/alta-18/Documents/Alterra/FlaskPractice/.flaskblog_venv/lib/python3.6/site-packages/sqlalchemy/orm/session.py", line 1036, in commit
    self.transaction.commit()
  File "/home/alta-18/Documents/Alterra/FlaskPractice/.flaskblog_venv/lib/python3.6/site-packages/sqlalchemy/orm/session.py", line 503, in commit
    self._prepare_impl()
  File "/home/alta-18/Documents/Alterra/FlaskPractice/.flaskblog_venv/lib/python3.6/site-packages/sqlalchemy/orm/session.py", line 482, in _prepare_impl
    self.session.flush()
  File "/home/alta-18/Documents/Alterra/FlaskPractice/.flaskblog_venv/lib/python3.6/site-packages/sqlalchemy/orm/session.py", line 2479, in flush
    self._flush(objects)
  File "/home/alta-18/Documents/Alterra/FlaskPractice/.flaskblog_venv/lib/python3.6/site-packages/sqlalchemy/orm/session.py", line 2617, in _flush
    transaction.rollback(_capture_exception=True)
  File "/home/alta-18/Documents/Alterra/FlaskPractice/.flaskblog_venv/lib/python3.6/site-packages/sqlalchemy/util/langhelpers.py", line 68, in __exit__
    compat.reraise(exc_type, exc_value, exc_tb)
  File "/home/alta-18/Documents/Alterra/FlaskPractice/.flaskblog_venv/lib/python3.6/site-packages/sqlalchemy/util/compat.py", line 153, in reraise
    raise value
  File "/home/alta-18/Documents/Alterra/FlaskPractice/.flaskblog_venv/lib/python3.6/site-packages/sqlalchemy/orm/session.py", line 2577, in _flush
    flush_context.execute()
  File "/home/alta-18/Documents/Alterra/FlaskPractice/.flaskblog_venv/lib/python3.6/site-packages/sqlalchemy/orm/unitofwork.py", line 422, in execute
    rec.execute(self)
  File "/home/alta-18/Documents/Alterra/FlaskPractice/.flaskblog_venv/lib/python3.6/site-packages/sqlalchemy/orm/unitofwork.py", line 589, in execute
    uow,
  File "/home/alta-18/Documents/Alterra/FlaskPractice/.flaskblog_venv/lib/python3.6/site-packages/sqlalchemy/orm/persistence.py", line 245, in save_obj
    insert,
  File "/home/alta-18/Documents/Alterra/FlaskPractice/.flaskblog_venv/lib/python3.6/site-packages/sqlalchemy/orm/persistence.py", line 1137, in _emit_insert_statements
    statement, params
  File "/home/alta-18/Documents/Alterra/FlaskPractice/.flaskblog_venv/lib/python3.6/site-packages/sqlalchemy/engine/base.py", line 982, in execute
    return meth(self, multiparams, params)
  File "/home/alta-18/Documents/Alterra/FlaskPractice/.flaskblog_venv/lib/python3.6/site-packages/sqlalchemy/sql/elements.py", line 287, in _execute_on_connection
    return connection._execute_clauseelement(self, multiparams, params)
  File "/home/alta-18/Documents/Alterra/FlaskPractice/.flaskblog_venv/lib/python3.6/site-packages/sqlalchemy/engine/base.py", line 1101, in _execute_clauseelement
    distilled_params,
  File "/home/alta-18/Documents/Alterra/FlaskPractice/.flaskblog_venv/lib/python3.6/site-packages/sqlalchemy/engine/base.py", line 1250, in _execute_context
    e, statement, parameters, cursor, context
  File "/home/alta-18/Documents/Alterra/FlaskPractice/.flaskblog_venv/lib/python3.6/site-packages/sqlalchemy/engine/base.py", line 1476, in _handle_dbapi_exception
    util.raise_from_cause(sqlalchemy_exception, exc_info)
  File "/home/alta-18/Documents/Alterra/FlaskPractice/.flaskblog_venv/lib/python3.6/site-packages/sqlalchemy/util/compat.py", line 398, in raise_from_cause
    reraise(type(exception), exception, tb=exc_tb, cause=cause)
  File "/home/alta-18/Documents/Alterra/FlaskPractice/.flaskblog_venv/lib/python3.6/site-packages/sqlalchemy/util/compat.py", line 152, in reraise
    raise value.with_traceback(tb)
  File "/home/alta-18/Documents/Alterra/FlaskPractice/.flaskblog_venv/lib/python3.6/site-packages/sqlalchemy/engine/base.py", line 1246, in _execute_context
    cursor, statement, parameters, context
  File "/home/alta-18/Documents/Alterra/FlaskPractice/.flaskblog_venv/lib/python3.6/site-packages/sqlalchemy/engine/default.py", line 581, in do_execute
    cursor.execute(statement, parameters)
  File "/home/alta-18/Documents/Alterra/FlaskPractice/.flaskblog_venv/lib/python3.6/site-packages/pymysql/cursors.py", line 170, in execute
    result = self._query(query)
  File "/home/alta-18/Documents/Alterra/FlaskPractice/.flaskblog_venv/lib/python3.6/site-packages/pymysql/cursors.py", line 328, in _query
    conn.query(q)
  File "/home/alta-18/Documents/Alterra/FlaskPractice/.flaskblog_venv/lib/python3.6/site-packages/pymysql/connections.py", line 517, in query
    self._affected_rows = self._read_query_result(unbuffered=unbuffered)
  File "/home/alta-18/Documents/Alterra/FlaskPractice/.flaskblog_venv/lib/python3.6/site-packages/pymysql/connections.py", line 732, in _read_query_result
    result.read()
  File "/home/alta-18/Documents/Alterra/FlaskPractice/.flaskblog_venv/lib/python3.6/site-packages/pymysql/connections.py", line 1075, in read
    first_packet = self.connection._read_packet()
  File "/home/alta-18/Documents/Alterra/FlaskPractice/.flaskblog_venv/lib/python3.6/site-packages/pymysql/connections.py", line 684, in _read_packet
    packet.check_error()
  File "/home/alta-18/Documents/Alterra/FlaskPractice/.flaskblog_venv/lib/python3.6/site-packages/pymysql/protocol.py", line 220, in check_error
    err.raise_mysql_exception(self._data)
  File "/home/alta-18/Documents/Alterra/FlaskPractice/.flaskblog_venv/lib/python3.6/site-packages/pymysql/err.py", line 109, in raise_mysql_exception
    raise errorclass(errno, errval)
sqlalchemy.exc.IntegrityError: (pymysql.err.IntegrityError) (1048, "Column 'updated_at' cannot be null")
[SQL: INSERT INTO users (name, age, sex, created_at, updated_at) VALUES (%(name)s, %(age)s, %(sex)s, %(created_at)s, %(updated_at)s)]
[parameters: {'name': 'Wildan', 'age': 22, 'sex': 'Male', 'created_at': datetime.datetime(2019, 12, 17, 17, 35, 50, 911160), 'updated_at': None}]
(Background on this error at: http://sqlalche.me/e/gkpj)
[2019-12-17 17:36:06,389] {/home/alta-18/Documents/Alterra/FlaskPractice/blueprints/__init__.py:43} ERROR - REQUEST_LOG	{"method": "POST", "code": "500 INTERNAL SERVER ERROR", "request": {"name": "Wildan", "age": 22, "sex": "Male"}, "response": {"message": "Internal Server Error"}}
[2019-12-17 17:37:18,501] {/home/alta-18/Documents/Alterra/FlaskPractice/.flaskblog_venv/lib/python3.6/site-packages/flask/app.py:1891} ERROR - Exception on /user [POST]
Traceback (most recent call last):
  File "/home/alta-18/Documents/Alterra/FlaskPractice/.flaskblog_venv/lib/python3.6/site-packages/sqlalchemy/engine/base.py", line 1246, in _execute_context
    cursor, statement, parameters, context
  File "/home/alta-18/Documents/Alterra/FlaskPractice/.flaskblog_venv/lib/python3.6/site-packages/sqlalchemy/engine/default.py", line 581, in do_execute
    cursor.execute(statement, parameters)
  File "/home/alta-18/Documents/Alterra/FlaskPractice/.flaskblog_venv/lib/python3.6/site-packages/pymysql/cursors.py", line 170, in execute
    result = self._query(query)
  File "/home/alta-18/Documents/Alterra/FlaskPractice/.flaskblog_venv/lib/python3.6/site-packages/pymysql/cursors.py", line 328, in _query
    conn.query(q)
  File "/home/alta-18/Documents/Alterra/FlaskPractice/.flaskblog_venv/lib/python3.6/site-packages/pymysql/connections.py", line 517, in query
    self._affected_rows = self._read_query_result(unbuffered=unbuffered)
  File "/home/alta-18/Documents/Alterra/FlaskPractice/.flaskblog_venv/lib/python3.6/site-packages/pymysql/connections.py", line 732, in _read_query_result
    result.read()
  File "/home/alta-18/Documents/Alterra/FlaskPractice/.flaskblog_venv/lib/python3.6/site-packages/pymysql/connections.py", line 1075, in read
    first_packet = self.connection._read_packet()
  File "/home/alta-18/Documents/Alterra/FlaskPractice/.flaskblog_venv/lib/python3.6/site-packages/pymysql/connections.py", line 684, in _read_packet
    packet.check_error()
  File "/home/alta-18/Documents/Alterra/FlaskPractice/.flaskblog_venv/lib/python3.6/site-packages/pymysql/protocol.py", line 220, in check_error
    err.raise_mysql_exception(self._data)
  File "/home/alta-18/Documents/Alterra/FlaskPractice/.flaskblog_venv/lib/python3.6/site-packages/pymysql/err.py", line 109, in raise_mysql_exception
    raise errorclass(errno, errval)
pymysql.err.IntegrityError: (1048, "Column 'updated_at' cannot be null")

The above exception was the direct cause of the following exception:

Traceback (most recent call last):
  File "/home/alta-18/Documents/Alterra/FlaskPractice/.flaskblog_venv/lib/python3.6/site-packages/flask/app.py", line 1949, in full_dispatch_request
    rv = self.dispatch_request()
  File "/home/alta-18/Documents/Alterra/FlaskPractice/.flaskblog_venv/lib/python3.6/site-packages/flask/app.py", line 1935, in dispatch_request
    return self.view_functions[rule.endpoint](**req.view_args)
  File "/home/alta-18/Documents/Alterra/FlaskPractice/.flaskblog_venv/lib/python3.6/site-packages/flask_restful/__init__.py", line 458, in wrapper
    resp = resource(*args, **kwargs)
  File "/home/alta-18/Documents/Alterra/FlaskPractice/.flaskblog_venv/lib/python3.6/site-packages/flask/views.py", line 89, in view
    return self.dispatch_request(*args, **kwargs)
  File "/home/alta-18/Documents/Alterra/FlaskPractice/.flaskblog_venv/lib/python3.6/site-packages/flask_restful/__init__.py", line 573, in dispatch_request
    resp = meth(*args, **kwargs)
  File "/home/alta-18/Documents/Alterra/FlaskPractice/blueprints/user/resources.py", line 54, in post
    db.session.commit()
  File "/home/alta-18/Documents/Alterra/FlaskPractice/.flaskblog_venv/lib/python3.6/site-packages/sqlalchemy/orm/scoping.py", line 162, in do
    return getattr(self.registry(), name)(*args, **kwargs)
  File "/home/alta-18/Documents/Alterra/FlaskPractice/.flaskblog_venv/lib/python3.6/site-packages/sqlalchemy/orm/session.py", line 1036, in commit
    self.transaction.commit()
  File "/home/alta-18/Documents/Alterra/FlaskPractice/.flaskblog_venv/lib/python3.6/site-packages/sqlalchemy/orm/session.py", line 503, in commit
    self._prepare_impl()
  File "/home/alta-18/Documents/Alterra/FlaskPractice/.flaskblog_venv/lib/python3.6/site-packages/sqlalchemy/orm/session.py", line 482, in _prepare_impl
    self.session.flush()
  File "/home/alta-18/Documents/Alterra/FlaskPractice/.flaskblog_venv/lib/python3.6/site-packages/sqlalchemy/orm/session.py", line 2479, in flush
    self._flush(objects)
  File "/home/alta-18/Documents/Alterra/FlaskPractice/.flaskblog_venv/lib/python3.6/site-packages/sqlalchemy/orm/session.py", line 2617, in _flush
    transaction.rollback(_capture_exception=True)
  File "/home/alta-18/Documents/Alterra/FlaskPractice/.flaskblog_venv/lib/python3.6/site-packages/sqlalchemy/util/langhelpers.py", line 68, in __exit__
    compat.reraise(exc_type, exc_value, exc_tb)
  File "/home/alta-18/Documents/Alterra/FlaskPractice/.flaskblog_venv/lib/python3.6/site-packages/sqlalchemy/util/compat.py", line 153, in reraise
    raise value
  File "/home/alta-18/Documents/Alterra/FlaskPractice/.flaskblog_venv/lib/python3.6/site-packages/sqlalchemy/orm/session.py", line 2577, in _flush
    flush_context.execute()
  File "/home/alta-18/Documents/Alterra/FlaskPractice/.flaskblog_venv/lib/python3.6/site-packages/sqlalchemy/orm/unitofwork.py", line 422, in execute
    rec.execute(self)
  File "/home/alta-18/Documents/Alterra/FlaskPractice/.flaskblog_venv/lib/python3.6/site-packages/sqlalchemy/orm/unitofwork.py", line 589, in execute
    uow,
  File "/home/alta-18/Documents/Alterra/FlaskPractice/.flaskblog_venv/lib/python3.6/site-packages/sqlalchemy/orm/persistence.py", line 245, in save_obj
    insert,
  File "/home/alta-18/Documents/Alterra/FlaskPractice/.flaskblog_venv/lib/python3.6/site-packages/sqlalchemy/orm/persistence.py", line 1137, in _emit_insert_statements
    statement, params
  File "/home/alta-18/Documents/Alterra/FlaskPractice/.flaskblog_venv/lib/python3.6/site-packages/sqlalchemy/engine/base.py", line 982, in execute
    return meth(self, multiparams, params)
  File "/home/alta-18/Documents/Alterra/FlaskPractice/.flaskblog_venv/lib/python3.6/site-packages/sqlalchemy/sql/elements.py", line 287, in _execute_on_connection
    return connection._execute_clauseelement(self, multiparams, params)
  File "/home/alta-18/Documents/Alterra/FlaskPractice/.flaskblog_venv/lib/python3.6/site-packages/sqlalchemy/engine/base.py", line 1101, in _execute_clauseelement
    distilled_params,
  File "/home/alta-18/Documents/Alterra/FlaskPractice/.flaskblog_venv/lib/python3.6/site-packages/sqlalchemy/engine/base.py", line 1250, in _execute_context
    e, statement, parameters, cursor, context
  File "/home/alta-18/Documents/Alterra/FlaskPractice/.flaskblog_venv/lib/python3.6/site-packages/sqlalchemy/engine/base.py", line 1476, in _handle_dbapi_exception
    util.raise_from_cause(sqlalchemy_exception, exc_info)
  File "/home/alta-18/Documents/Alterra/FlaskPractice/.flaskblog_venv/lib/python3.6/site-packages/sqlalchemy/util/compat.py", line 398, in raise_from_cause
    reraise(type(exception), exception, tb=exc_tb, cause=cause)
  File "/home/alta-18/Documents/Alterra/FlaskPractice/.flaskblog_venv/lib/python3.6/site-packages/sqlalchemy/util/compat.py", line 152, in reraise
    raise value.with_traceback(tb)
  File "/home/alta-18/Documents/Alterra/FlaskPractice/.flaskblog_venv/lib/python3.6/site-packages/sqlalchemy/engine/base.py", line 1246, in _execute_context
    cursor, statement, parameters, context
  File "/home/alta-18/Documents/Alterra/FlaskPractice/.flaskblog_venv/lib/python3.6/site-packages/sqlalchemy/engine/default.py", line 581, in do_execute
    cursor.execute(statement, parameters)
  File "/home/alta-18/Documents/Alterra/FlaskPractice/.flaskblog_venv/lib/python3.6/site-packages/pymysql/cursors.py", line 170, in execute
    result = self._query(query)
  File "/home/alta-18/Documents/Alterra/FlaskPractice/.flaskblog_venv/lib/python3.6/site-packages/pymysql/cursors.py", line 328, in _query
    conn.query(q)
  File "/home/alta-18/Documents/Alterra/FlaskPractice/.flaskblog_venv/lib/python3.6/site-packages/pymysql/connections.py", line 517, in query
    self._affected_rows = self._read_query_result(unbuffered=unbuffered)
  File "/home/alta-18/Documents/Alterra/FlaskPractice/.flaskblog_venv/lib/python3.6/site-packages/pymysql/connections.py", line 732, in _read_query_result
    result.read()
  File "/home/alta-18/Documents/Alterra/FlaskPractice/.flaskblog_venv/lib/python3.6/site-packages/pymysql/connections.py", line 1075, in read
    first_packet = self.connection._read_packet()
  File "/home/alta-18/Documents/Alterra/FlaskPractice/.flaskblog_venv/lib/python3.6/site-packages/pymysql/connections.py", line 684, in _read_packet
    packet.check_error()
  File "/home/alta-18/Documents/Alterra/FlaskPractice/.flaskblog_venv/lib/python3.6/site-packages/pymysql/protocol.py", line 220, in check_error
    err.raise_mysql_exception(self._data)
  File "/home/alta-18/Documents/Alterra/FlaskPractice/.flaskblog_venv/lib/python3.6/site-packages/pymysql/err.py", line 109, in raise_mysql_exception
    raise errorclass(errno, errval)
sqlalchemy.exc.IntegrityError: (pymysql.err.IntegrityError) (1048, "Column 'updated_at' cannot be null")
[SQL: INSERT INTO users (name, age, sex, created_at, updated_at) VALUES (%(name)s, %(age)s, %(sex)s, %(created_at)s, %(updated_at)s)]
[parameters: {'name': 'Wildan', 'age': 22, 'sex': 'Male', 'created_at': datetime.datetime(2019, 12, 17, 17, 35, 50, 911160), 'updated_at': None}]
(Background on this error at: http://sqlalche.me/e/gkpj)
[2019-12-17 17:37:18,503] {/home/alta-18/Documents/Alterra/FlaskPractice/blueprints/__init__.py:43} ERROR - REQUEST_LOG	{"method": "POST", "code": "500 INTERNAL SERVER ERROR", "request": {"name": "Wildan", "age": 22, "sex": "Male"}, "response": {"message": "Internal Server Error"}}
[2019-12-17 17:39:12,077] {/home/alta-18/Documents/Alterra/FlaskPractice/.flaskblog_venv/lib/python3.6/site-packages/flask/app.py:1891} ERROR - Exception on /user [POST]
Traceback (most recent call last):
  File "/home/alta-18/Documents/Alterra/FlaskPractice/.flaskblog_venv/lib/python3.6/site-packages/sqlalchemy/engine/base.py", line 1246, in _execute_context
    cursor, statement, parameters, context
  File "/home/alta-18/Documents/Alterra/FlaskPractice/.flaskblog_venv/lib/python3.6/site-packages/sqlalchemy/engine/default.py", line 581, in do_execute
    cursor.execute(statement, parameters)
  File "/home/alta-18/Documents/Alterra/FlaskPractice/.flaskblog_venv/lib/python3.6/site-packages/pymysql/cursors.py", line 170, in execute
    result = self._query(query)
  File "/home/alta-18/Documents/Alterra/FlaskPractice/.flaskblog_venv/lib/python3.6/site-packages/pymysql/cursors.py", line 328, in _query
    conn.query(q)
  File "/home/alta-18/Documents/Alterra/FlaskPractice/.flaskblog_venv/lib/python3.6/site-packages/pymysql/connections.py", line 517, in query
    self._affected_rows = self._read_query_result(unbuffered=unbuffered)
  File "/home/alta-18/Documents/Alterra/FlaskPractice/.flaskblog_venv/lib/python3.6/site-packages/pymysql/connections.py", line 732, in _read_query_result
    result.read()
  File "/home/alta-18/Documents/Alterra/FlaskPractice/.flaskblog_venv/lib/python3.6/site-packages/pymysql/connections.py", line 1075, in read
    first_packet = self.connection._read_packet()
  File "/home/alta-18/Documents/Alterra/FlaskPractice/.flaskblog_venv/lib/python3.6/site-packages/pymysql/connections.py", line 684, in _read_packet
    packet.check_error()
  File "/home/alta-18/Documents/Alterra/FlaskPractice/.flaskblog_venv/lib/python3.6/site-packages/pymysql/protocol.py", line 220, in check_error
    err.raise_mysql_exception(self._data)
  File "/home/alta-18/Documents/Alterra/FlaskPractice/.flaskblog_venv/lib/python3.6/site-packages/pymysql/err.py", line 109, in raise_mysql_exception
    raise errorclass(errno, errval)
pymysql.err.IntegrityError: (1048, "Column 'updated_at' cannot be null")

The above exception was the direct cause of the following exception:

Traceback (most recent call last):
  File "/home/alta-18/Documents/Alterra/FlaskPractice/.flaskblog_venv/lib/python3.6/site-packages/flask/app.py", line 1949, in full_dispatch_request
    rv = self.dispatch_request()
  File "/home/alta-18/Documents/Alterra/FlaskPractice/.flaskblog_venv/lib/python3.6/site-packages/flask/app.py", line 1935, in dispatch_request
    return self.view_functions[rule.endpoint](**req.view_args)
  File "/home/alta-18/Documents/Alterra/FlaskPractice/.flaskblog_venv/lib/python3.6/site-packages/flask_restful/__init__.py", line 458, in wrapper
    resp = resource(*args, **kwargs)
  File "/home/alta-18/Documents/Alterra/FlaskPractice/.flaskblog_venv/lib/python3.6/site-packages/flask/views.py", line 89, in view
    return self.dispatch_request(*args, **kwargs)
  File "/home/alta-18/Documents/Alterra/FlaskPractice/.flaskblog_venv/lib/python3.6/site-packages/flask_restful/__init__.py", line 573, in dispatch_request
    resp = meth(*args, **kwargs)
  File "/home/alta-18/Documents/Alterra/FlaskPractice/blueprints/user/resources.py", line 54, in post
    db.session.commit()
  File "/home/alta-18/Documents/Alterra/FlaskPractice/.flaskblog_venv/lib/python3.6/site-packages/sqlalchemy/orm/scoping.py", line 162, in do
    return getattr(self.registry(), name)(*args, **kwargs)
  File "/home/alta-18/Documents/Alterra/FlaskPractice/.flaskblog_venv/lib/python3.6/site-packages/sqlalchemy/orm/session.py", line 1036, in commit
    self.transaction.commit()
  File "/home/alta-18/Documents/Alterra/FlaskPractice/.flaskblog_venv/lib/python3.6/site-packages/sqlalchemy/orm/session.py", line 503, in commit
    self._prepare_impl()
  File "/home/alta-18/Documents/Alterra/FlaskPractice/.flaskblog_venv/lib/python3.6/site-packages/sqlalchemy/orm/session.py", line 482, in _prepare_impl
    self.session.flush()
  File "/home/alta-18/Documents/Alterra/FlaskPractice/.flaskblog_venv/lib/python3.6/site-packages/sqlalchemy/orm/session.py", line 2479, in flush
    self._flush(objects)
  File "/home/alta-18/Documents/Alterra/FlaskPractice/.flaskblog_venv/lib/python3.6/site-packages/sqlalchemy/orm/session.py", line 2617, in _flush
    transaction.rollback(_capture_exception=True)
  File "/home/alta-18/Documents/Alterra/FlaskPractice/.flaskblog_venv/lib/python3.6/site-packages/sqlalchemy/util/langhelpers.py", line 68, in __exit__
    compat.reraise(exc_type, exc_value, exc_tb)
  File "/home/alta-18/Documents/Alterra/FlaskPractice/.flaskblog_venv/lib/python3.6/site-packages/sqlalchemy/util/compat.py", line 153, in reraise
    raise value
  File "/home/alta-18/Documents/Alterra/FlaskPractice/.flaskblog_venv/lib/python3.6/site-packages/sqlalchemy/orm/session.py", line 2577, in _flush
    flush_context.execute()
  File "/home/alta-18/Documents/Alterra/FlaskPractice/.flaskblog_venv/lib/python3.6/site-packages/sqlalchemy/orm/unitofwork.py", line 422, in execute
    rec.execute(self)
  File "/home/alta-18/Documents/Alterra/FlaskPractice/.flaskblog_venv/lib/python3.6/site-packages/sqlalchemy/orm/unitofwork.py", line 589, in execute
    uow,
  File "/home/alta-18/Documents/Alterra/FlaskPractice/.flaskblog_venv/lib/python3.6/site-packages/sqlalchemy/orm/persistence.py", line 245, in save_obj
    insert,
  File "/home/alta-18/Documents/Alterra/FlaskPractice/.flaskblog_venv/lib/python3.6/site-packages/sqlalchemy/orm/persistence.py", line 1137, in _emit_insert_statements
    statement, params
  File "/home/alta-18/Documents/Alterra/FlaskPractice/.flaskblog_venv/lib/python3.6/site-packages/sqlalchemy/engine/base.py", line 982, in execute
    return meth(self, multiparams, params)
  File "/home/alta-18/Documents/Alterra/FlaskPractice/.flaskblog_venv/lib/python3.6/site-packages/sqlalchemy/sql/elements.py", line 287, in _execute_on_connection
    return connection._execute_clauseelement(self, multiparams, params)
  File "/home/alta-18/Documents/Alterra/FlaskPractice/.flaskblog_venv/lib/python3.6/site-packages/sqlalchemy/engine/base.py", line 1101, in _execute_clauseelement
    distilled_params,
  File "/home/alta-18/Documents/Alterra/FlaskPractice/.flaskblog_venv/lib/python3.6/site-packages/sqlalchemy/engine/base.py", line 1250, in _execute_context
    e, statement, parameters, cursor, context
  File "/home/alta-18/Documents/Alterra/FlaskPractice/.flaskblog_venv/lib/python3.6/site-packages/sqlalchemy/engine/base.py", line 1476, in _handle_dbapi_exception
    util.raise_from_cause(sqlalchemy_exception, exc_info)
  File "/home/alta-18/Documents/Alterra/FlaskPractice/.flaskblog_venv/lib/python3.6/site-packages/sqlalchemy/util/compat.py", line 398, in raise_from_cause
    reraise(type(exception), exception, tb=exc_tb, cause=cause)
  File "/home/alta-18/Documents/Alterra/FlaskPractice/.flaskblog_venv/lib/python3.6/site-packages/sqlalchemy/util/compat.py", line 152, in reraise
    raise value.with_traceback(tb)
  File "/home/alta-18/Documents/Alterra/FlaskPractice/.flaskblog_venv/lib/python3.6/site-packages/sqlalchemy/engine/base.py", line 1246, in _execute_context
    cursor, statement, parameters, context
  File "/home/alta-18/Documents/Alterra/FlaskPractice/.flaskblog_venv/lib/python3.6/site-packages/sqlalchemy/engine/default.py", line 581, in do_execute
    cursor.execute(statement, parameters)
  File "/home/alta-18/Documents/Alterra/FlaskPractice/.flaskblog_venv/lib/python3.6/site-packages/pymysql/cursors.py", line 170, in execute
    result = self._query(query)
  File "/home/alta-18/Documents/Alterra/FlaskPractice/.flaskblog_venv/lib/python3.6/site-packages/pymysql/cursors.py", line 328, in _query
    conn.query(q)
  File "/home/alta-18/Documents/Alterra/FlaskPractice/.flaskblog_venv/lib/python3.6/site-packages/pymysql/connections.py", line 517, in query
    self._affected_rows = self._read_query_result(unbuffered=unbuffered)
  File "/home/alta-18/Documents/Alterra/FlaskPractice/.flaskblog_venv/lib/python3.6/site-packages/pymysql/connections.py", line 732, in _read_query_result
    result.read()
  File "/home/alta-18/Documents/Alterra/FlaskPractice/.flaskblog_venv/lib/python3.6/site-packages/pymysql/connections.py", line 1075, in read
    first_packet = self.connection._read_packet()
  File "/home/alta-18/Documents/Alterra/FlaskPractice/.flaskblog_venv/lib/python3.6/site-packages/pymysql/connections.py", line 684, in _read_packet
    packet.check_error()
  File "/home/alta-18/Documents/Alterra/FlaskPractice/.flaskblog_venv/lib/python3.6/site-packages/pymysql/protocol.py", line 220, in check_error
    err.raise_mysql_exception(self._data)
  File "/home/alta-18/Documents/Alterra/FlaskPractice/.flaskblog_venv/lib/python3.6/site-packages/pymysql/err.py", line 109, in raise_mysql_exception
    raise errorclass(errno, errval)
sqlalchemy.exc.IntegrityError: (pymysql.err.IntegrityError) (1048, "Column 'updated_at' cannot be null")
[SQL: INSERT INTO users (name, age, sex, created_at, updated_at) VALUES (%(name)s, %(age)s, %(sex)s, %(created_at)s, %(updated_at)s)]
[parameters: {'name': 'Wildan', 'age': 22, 'sex': 'Male', 'created_at': datetime.datetime(2019, 12, 17, 17, 39, 8, 331928), 'updated_at': None}]
(Background on this error at: http://sqlalche.me/e/gkpj)
[2019-12-17 17:39:12,091] {/home/alta-18/Documents/Alterra/FlaskPractice/blueprints/__init__.py:43} ERROR - REQUEST_LOG	{"method": "POST", "code": "500 INTERNAL SERVER ERROR", "request": {"name": "Wildan", "age": 22, "sex": "Male"}, "response": {"message": "Internal Server Error"}}
[2019-12-17 17:41:54,241] {/home/alta-18/Documents/Alterra/FlaskPractice/.flaskblog_venv/lib/python3.6/site-packages/flask/app.py:1891} ERROR - Exception on /user/1 [POST]
Traceback (most recent call last):
  File "/home/alta-18/Documents/Alterra/FlaskPractice/.flaskblog_venv/lib/python3.6/site-packages/flask/app.py", line 1949, in full_dispatch_request
    rv = self.dispatch_request()
  File "/home/alta-18/Documents/Alterra/FlaskPractice/.flaskblog_venv/lib/python3.6/site-packages/flask/app.py", line 1935, in dispatch_request
    return self.view_functions[rule.endpoint](**req.view_args)
  File "/home/alta-18/Documents/Alterra/FlaskPractice/.flaskblog_venv/lib/python3.6/site-packages/flask_restful/__init__.py", line 458, in wrapper
    resp = resource(*args, **kwargs)
  File "/home/alta-18/Documents/Alterra/FlaskPractice/.flaskblog_venv/lib/python3.6/site-packages/flask/views.py", line 89, in view
    return self.dispatch_request(*args, **kwargs)
  File "/home/alta-18/Documents/Alterra/FlaskPractice/.flaskblog_venv/lib/python3.6/site-packages/flask_restful/__init__.py", line 573, in dispatch_request
    resp = meth(*args, **kwargs)
TypeError: post() got an unexpected keyword argument 'id'
[2019-12-17 17:41:54,242] {/home/alta-18/Documents/Alterra/FlaskPractice/blueprints/__init__.py:43} ERROR - REQUEST_LOG	{"method": "POST", "code": "500 INTERNAL SERVER ERROR", "request": {"name": "Wildan", "age": 22, "sex": "Male"}, "response": {"message": "Internal Server Error"}}
[2019-12-17 17:42:49,298] {/home/alta-18/Documents/Alterra/FlaskPractice/.flaskblog_venv/lib/python3.6/site-packages/flask/app.py:1891} ERROR - Exception on /user [POST]
Traceback (most recent call last):
  File "/home/alta-18/Documents/Alterra/FlaskPractice/.flaskblog_venv/lib/python3.6/site-packages/sqlalchemy/engine/base.py", line 1246, in _execute_context
    cursor, statement, parameters, context
  File "/home/alta-18/Documents/Alterra/FlaskPractice/.flaskblog_venv/lib/python3.6/site-packages/sqlalchemy/engine/default.py", line 581, in do_execute
    cursor.execute(statement, parameters)
  File "/home/alta-18/Documents/Alterra/FlaskPractice/.flaskblog_venv/lib/python3.6/site-packages/pymysql/cursors.py", line 170, in execute
    result = self._query(query)
  File "/home/alta-18/Documents/Alterra/FlaskPractice/.flaskblog_venv/lib/python3.6/site-packages/pymysql/cursors.py", line 328, in _query
    conn.query(q)
  File "/home/alta-18/Documents/Alterra/FlaskPractice/.flaskblog_venv/lib/python3.6/site-packages/pymysql/connections.py", line 517, in query
    self._affected_rows = self._read_query_result(unbuffered=unbuffered)
  File "/home/alta-18/Documents/Alterra/FlaskPractice/.flaskblog_venv/lib/python3.6/site-packages/pymysql/connections.py", line 732, in _read_query_result
    result.read()
  File "/home/alta-18/Documents/Alterra/FlaskPractice/.flaskblog_venv/lib/python3.6/site-packages/pymysql/connections.py", line 1075, in read
    first_packet = self.connection._read_packet()
  File "/home/alta-18/Documents/Alterra/FlaskPractice/.flaskblog_venv/lib/python3.6/site-packages/pymysql/connections.py", line 684, in _read_packet
    packet.check_error()
  File "/home/alta-18/Documents/Alterra/FlaskPractice/.flaskblog_venv/lib/python3.6/site-packages/pymysql/protocol.py", line 220, in check_error
    err.raise_mysql_exception(self._data)
  File "/home/alta-18/Documents/Alterra/FlaskPractice/.flaskblog_venv/lib/python3.6/site-packages/pymysql/err.py", line 109, in raise_mysql_exception
    raise errorclass(errno, errval)
pymysql.err.IntegrityError: (1048, "Column 'updated_at' cannot be null")

The above exception was the direct cause of the following exception:

Traceback (most recent call last):
  File "/home/alta-18/Documents/Alterra/FlaskPractice/.flaskblog_venv/lib/python3.6/site-packages/flask/app.py", line 1949, in full_dispatch_request
    rv = self.dispatch_request()
  File "/home/alta-18/Documents/Alterra/FlaskPractice/.flaskblog_venv/lib/python3.6/site-packages/flask/app.py", line 1935, in dispatch_request
    return self.view_functions[rule.endpoint](**req.view_args)
  File "/home/alta-18/Documents/Alterra/FlaskPractice/.flaskblog_venv/lib/python3.6/site-packages/flask_restful/__init__.py", line 458, in wrapper
    resp = resource(*args, **kwargs)
  File "/home/alta-18/Documents/Alterra/FlaskPractice/.flaskblog_venv/lib/python3.6/site-packages/flask/views.py", line 89, in view
    return self.dispatch_request(*args, **kwargs)
  File "/home/alta-18/Documents/Alterra/FlaskPractice/.flaskblog_venv/lib/python3.6/site-packages/flask_restful/__init__.py", line 573, in dispatch_request
    resp = meth(*args, **kwargs)
  File "/home/alta-18/Documents/Alterra/FlaskPractice/blueprints/user/resources.py", line 54, in post
    db.session.commit()
  File "/home/alta-18/Documents/Alterra/FlaskPractice/.flaskblog_venv/lib/python3.6/site-packages/sqlalchemy/orm/scoping.py", line 162, in do
    return getattr(self.registry(), name)(*args, **kwargs)
  File "/home/alta-18/Documents/Alterra/FlaskPractice/.flaskblog_venv/lib/python3.6/site-packages/sqlalchemy/orm/session.py", line 1036, in commit
    self.transaction.commit()
  File "/home/alta-18/Documents/Alterra/FlaskPractice/.flaskblog_venv/lib/python3.6/site-packages/sqlalchemy/orm/session.py", line 503, in commit
    self._prepare_impl()
  File "/home/alta-18/Documents/Alterra/FlaskPractice/.flaskblog_venv/lib/python3.6/site-packages/sqlalchemy/orm/session.py", line 482, in _prepare_impl
    self.session.flush()
  File "/home/alta-18/Documents/Alterra/FlaskPractice/.flaskblog_venv/lib/python3.6/site-packages/sqlalchemy/orm/session.py", line 2479, in flush
    self._flush(objects)
  File "/home/alta-18/Documents/Alterra/FlaskPractice/.flaskblog_venv/lib/python3.6/site-packages/sqlalchemy/orm/session.py", line 2617, in _flush
    transaction.rollback(_capture_exception=True)
  File "/home/alta-18/Documents/Alterra/FlaskPractice/.flaskblog_venv/lib/python3.6/site-packages/sqlalchemy/util/langhelpers.py", line 68, in __exit__
    compat.reraise(exc_type, exc_value, exc_tb)
  File "/home/alta-18/Documents/Alterra/FlaskPractice/.flaskblog_venv/lib/python3.6/site-packages/sqlalchemy/util/compat.py", line 153, in reraise
    raise value
  File "/home/alta-18/Documents/Alterra/FlaskPractice/.flaskblog_venv/lib/python3.6/site-packages/sqlalchemy/orm/session.py", line 2577, in _flush
    flush_context.execute()
  File "/home/alta-18/Documents/Alterra/FlaskPractice/.flaskblog_venv/lib/python3.6/site-packages/sqlalchemy/orm/unitofwork.py", line 422, in execute
    rec.execute(self)
  File "/home/alta-18/Documents/Alterra/FlaskPractice/.flaskblog_venv/lib/python3.6/site-packages/sqlalchemy/orm/unitofwork.py", line 589, in execute
    uow,
  File "/home/alta-18/Documents/Alterra/FlaskPractice/.flaskblog_venv/lib/python3.6/site-packages/sqlalchemy/orm/persistence.py", line 245, in save_obj
    insert,
  File "/home/alta-18/Documents/Alterra/FlaskPractice/.flaskblog_venv/lib/python3.6/site-packages/sqlalchemy/orm/persistence.py", line 1137, in _emit_insert_statements
    statement, params
  File "/home/alta-18/Documents/Alterra/FlaskPractice/.flaskblog_venv/lib/python3.6/site-packages/sqlalchemy/engine/base.py", line 982, in execute
    return meth(self, multiparams, params)
  File "/home/alta-18/Documents/Alterra/FlaskPractice/.flaskblog_venv/lib/python3.6/site-packages/sqlalchemy/sql/elements.py", line 287, in _execute_on_connection
    return connection._execute_clauseelement(self, multiparams, params)
  File "/home/alta-18/Documents/Alterra/FlaskPractice/.flaskblog_venv/lib/python3.6/site-packages/sqlalchemy/engine/base.py", line 1101, in _execute_clauseelement
    distilled_params,
  File "/home/alta-18/Documents/Alterra/FlaskPractice/.flaskblog_venv/lib/python3.6/site-packages/sqlalchemy/engine/base.py", line 1250, in _execute_context
    e, statement, parameters, cursor, context
  File "/home/alta-18/Documents/Alterra/FlaskPractice/.flaskblog_venv/lib/python3.6/site-packages/sqlalchemy/engine/base.py", line 1476, in _handle_dbapi_exception
    util.raise_from_cause(sqlalchemy_exception, exc_info)
  File "/home/alta-18/Documents/Alterra/FlaskPractice/.flaskblog_venv/lib/python3.6/site-packages/sqlalchemy/util/compat.py", line 398, in raise_from_cause
    reraise(type(exception), exception, tb=exc_tb, cause=cause)
  File "/home/alta-18/Documents/Alterra/FlaskPractice/.flaskblog_venv/lib/python3.6/site-packages/sqlalchemy/util/compat.py", line 152, in reraise
    raise value.with_traceback(tb)
  File "/home/alta-18/Documents/Alterra/FlaskPractice/.flaskblog_venv/lib/python3.6/site-packages/sqlalchemy/engine/base.py", line 1246, in _execute_context
    cursor, statement, parameters, context
  File "/home/alta-18/Documents/Alterra/FlaskPractice/.flaskblog_venv/lib/python3.6/site-packages/sqlalchemy/engine/default.py", line 581, in do_execute
    cursor.execute(statement, parameters)
  File "/home/alta-18/Documents/Alterra/FlaskPractice/.flaskblog_venv/lib/python3.6/site-packages/pymysql/cursors.py", line 170, in execute
    result = self._query(query)
  File "/home/alta-18/Documents/Alterra/FlaskPractice/.flaskblog_venv/lib/python3.6/site-packages/pymysql/cursors.py", line 328, in _query
    conn.query(q)
  File "/home/alta-18/Documents/Alterra/FlaskPractice/.flaskblog_venv/lib/python3.6/site-packages/pymysql/connections.py", line 517, in query
    self._affected_rows = self._read_query_result(unbuffered=unbuffered)
  File "/home/alta-18/Documents/Alterra/FlaskPractice/.flaskblog_venv/lib/python3.6/site-packages/pymysql/connections.py", line 732, in _read_query_result
    result.read()
  File "/home/alta-18/Documents/Alterra/FlaskPractice/.flaskblog_venv/lib/python3.6/site-packages/pymysql/connections.py", line 1075, in read
    first_packet = self.connection._read_packet()
  File "/home/alta-18/Documents/Alterra/FlaskPractice/.flaskblog_venv/lib/python3.6/site-packages/pymysql/connections.py", line 684, in _read_packet
    packet.check_error()
  File "/home/alta-18/Documents/Alterra/FlaskPractice/.flaskblog_venv/lib/python3.6/site-packages/pymysql/protocol.py", line 220, in check_error
    err.raise_mysql_exception(self._data)
  File "/home/alta-18/Documents/Alterra/FlaskPractice/.flaskblog_venv/lib/python3.6/site-packages/pymysql/err.py", line 109, in raise_mysql_exception
    raise errorclass(errno, errval)
sqlalchemy.exc.IntegrityError: (pymysql.err.IntegrityError) (1048, "Column 'updated_at' cannot be null")
[SQL: INSERT INTO users (name, age, sex, created_at, updated_at) VALUES (%(name)s, %(age)s, %(sex)s, %(created_at)s, %(updated_at)s)]
[parameters: {'name': 'Wildan', 'age': 22, 'sex': 'Male', 'created_at': datetime.datetime(2019, 12, 17, 17, 39, 8, 331928), 'updated_at': None}]
(Background on this error at: http://sqlalche.me/e/gkpj)
[2019-12-17 17:42:49,301] {/home/alta-18/Documents/Alterra/FlaskPractice/blueprints/__init__.py:43} ERROR - REQUEST_LOG	{"method": "POST", "code": "500 INTERNAL SERVER ERROR", "request": {"name": "Wildan", "age": 22, "sex": "Male"}, "response": {"message": "Internal Server Error"}}
[2019-12-17 17:45:15,442] {/home/alta-18/Documents/Alterra/FlaskPractice/blueprints/__init__.py:36} INFO - REQUEST_LOG	{"method": "POST", "code": "200 OK", "request": {"name": "Wildan", "age": 22, "sex": "Male"}, "response": {"id": 1, "name": "Wildan", "age": 22, "sex": "Male"}}
[2019-12-17 17:46:49,517] {/home/alta-18/Documents/Alterra/FlaskPractice/blueprints/__init__.py:36} INFO - REQUEST_LOG	{"method": "POST", "code": "200 OK", "request": {"name": "Wildan", "age": 22, "sex": "Male"}, "response": {"id": 2, "name": "Wildan", "age": 22, "sex": "Male"}}
[2019-12-17 17:47:44,034] {/home/alta-18/Documents/Alterra/FlaskPractice/blueprints/__init__.py:36} INFO - REQUEST_LOG	{"method": "GET", "code": "200 OK", "request": {"name": "Wildan", "age": 22, "sex": "Male"}, "response": [{"id": 1, "name": "Wildan", "age": 22, "sex": "Male"}, {"id": 2, "name": "Wildan", "age": 22, "sex": "Male"}]}
[2019-12-17 17:47:52,187] {/home/alta-18/Documents/Alterra/FlaskPractice/.flaskblog_venv/lib/python3.6/site-packages/flask/app.py:1891} ERROR - Exception on /user/2 [GET]
Traceback (most recent call last):
  File "/home/alta-18/Documents/Alterra/FlaskPractice/.flaskblog_venv/lib/python3.6/site-packages/flask/app.py", line 1949, in full_dispatch_request
    rv = self.dispatch_request()
  File "/home/alta-18/Documents/Alterra/FlaskPractice/.flaskblog_venv/lib/python3.6/site-packages/flask/app.py", line 1935, in dispatch_request
    return self.view_functions[rule.endpoint](**req.view_args)
  File "/home/alta-18/Documents/Alterra/FlaskPractice/.flaskblog_venv/lib/python3.6/site-packages/flask_restful/__init__.py", line 458, in wrapper
    resp = resource(*args, **kwargs)
  File "/home/alta-18/Documents/Alterra/FlaskPractice/.flaskblog_venv/lib/python3.6/site-packages/flask/views.py", line 89, in view
    return self.dispatch_request(*args, **kwargs)
  File "/home/alta-18/Documents/Alterra/FlaskPractice/.flaskblog_venv/lib/python3.6/site-packages/flask_restful/__init__.py", line 573, in dispatch_request
    resp = meth(*args, **kwargs)
  File "/home/alta-18/Documents/Alterra/FlaskPractice/blueprints/user/resources.py", line 41, in get
    for row in qry.all():
AttributeError: 'Users' object has no attribute 'all'
[2019-12-17 17:47:52,190] {/home/alta-18/Documents/Alterra/FlaskPractice/blueprints/__init__.py:43} ERROR - REQUEST_LOG	{"method": "GET", "code": "500 INTERNAL SERVER ERROR", "request": {"name": "Wildan", "age": 22, "sex": "Male"}, "response": {"message": "Internal Server Error"}}
[2019-12-17 17:47:59,988] {/home/alta-18/Documents/Alterra/FlaskPractice/.flaskblog_venv/lib/python3.6/site-packages/flask/app.py:1891} ERROR - Exception on /user/1 [GET]
Traceback (most recent call last):
  File "/home/alta-18/Documents/Alterra/FlaskPractice/.flaskblog_venv/lib/python3.6/site-packages/flask/app.py", line 1949, in full_dispatch_request
    rv = self.dispatch_request()
  File "/home/alta-18/Documents/Alterra/FlaskPractice/.flaskblog_venv/lib/python3.6/site-packages/flask/app.py", line 1935, in dispatch_request
    return self.view_functions[rule.endpoint](**req.view_args)
  File "/home/alta-18/Documents/Alterra/FlaskPractice/.flaskblog_venv/lib/python3.6/site-packages/flask_restful/__init__.py", line 458, in wrapper
    resp = resource(*args, **kwargs)
  File "/home/alta-18/Documents/Alterra/FlaskPractice/.flaskblog_venv/lib/python3.6/site-packages/flask/views.py", line 89, in view
    return self.dispatch_request(*args, **kwargs)
  File "/home/alta-18/Documents/Alterra/FlaskPractice/.flaskblog_venv/lib/python3.6/site-packages/flask_restful/__init__.py", line 573, in dispatch_request
    resp = meth(*args, **kwargs)
  File "/home/alta-18/Documents/Alterra/FlaskPractice/blueprints/user/resources.py", line 41, in get
    for row in qry.all():
AttributeError: 'Users' object has no attribute 'all'
[2019-12-17 17:47:59,989] {/home/alta-18/Documents/Alterra/FlaskPractice/blueprints/__init__.py:43} ERROR - REQUEST_LOG	{"method": "GET", "code": "500 INTERNAL SERVER ERROR", "request": {"name": "Wildan", "age": 22, "sex": "Male"}, "response": {"message": "Internal Server Error"}}
[2019-12-17 17:51:01,138] {/home/alta-18/Documents/Alterra/FlaskPractice/blueprints/__init__.py:36} INFO - REQUEST_LOG	{"method": "GET", "code": "200 OK", "request": {"name": "Wildan", "age": 22, "sex": "Male"}, "response": [{"created_at": "Tue, 17 Dec 2019 17:45:04 -0000", "updated_at": null, "id": 1, "name": "Wildan", "age": 22, "sex": "Male"}, {"created_at": "Tue, 17 Dec 2019 17:46:45 -0000", "updated_at": "Tue, 17 Dec 2019 17:46:45 -0000", "id": 2, "name": "Wildan", "age": 22, "sex": "Male"}]}
[2019-12-17 17:51:13,329] {/home/alta-18/Documents/Alterra/FlaskPractice/blueprints/__init__.py:36} INFO - REQUEST_LOG	{"method": "GET", "code": "200 OK", "request": {"name": "Wildan", "age": 22, "sex": "Male"}, "response": {"created_at": "Tue, 17 Dec 2019 17:45:04 -0000", "updated_at": null, "id": 1, "name": "Wildan", "age": 22, "sex": "Male"}}
[2019-12-17 17:51:21,893] {/home/alta-18/Documents/Alterra/FlaskPractice/blueprints/__init__.py:43} ERROR - REQUEST_LOG	{"method": "GET", "code": "404 NOT FOUND", "request": {"name": "Wildan", "age": 22, "sex": "Male"}, "response": {"message": "NOT_FOUND"}}
[2019-12-17 17:51:27,812] {/home/alta-18/Documents/Alterra/FlaskPractice/blueprints/__init__.py:36} INFO - REQUEST_LOG	{"method": "GET", "code": "200 OK", "request": {"name": "Wildan", "age": 22, "sex": "Male"}, "response": {"created_at": "Tue, 17 Dec 2019 17:45:04 -0000", "updated_at": null, "id": 1, "name": "Wildan", "age": 22, "sex": "Male"}}
[2019-12-17 18:23:30,410] {/home/alta-18/Documents/Alterra/FlaskPractice/blueprints/__init__.py:36} INFO - REQUEST_LOG	{"method": "GET", "code": "200 OK", "request": {"name": "Wildan", "age": 22, "sex": "Male"}, "response": {"created_at": "Tue, 17 Dec 2019 17:45:04 -0000", "updated_at": null, "id": 1, "name": "Wildan", "age": 22, "sex": "Male"}}
[2019-12-17 18:23:36,270] {/home/alta-18/Documents/Alterra/FlaskPractice/blueprints/__init__.py:43} ERROR - REQUEST_LOG	{"method": "GET", "code": "404 NOT FOUND", "request": {"name": "Wildan", "age": 22, "sex": "Male"}, "response": {"message": "The requested URL was not found on the server. If you entered the URL manually please check your spelling and try again."}}
[2019-12-17 18:23:39,682] {/home/alta-18/Documents/Alterra/FlaskPractice/blueprints/__init__.py:36} INFO - REQUEST_LOG	{"method": "GET", "code": "200 OK", "request": {"name": "Wildan", "age": 22, "sex": "Male"}, "response": [{"created_at": "Tue, 17 Dec 2019 17:45:04 -0000", "updated_at": null, "id": 1, "name": "Wildan", "age": 22, "sex": "Male"}, {"created_at": "Tue, 17 Dec 2019 17:46:45 -0000", "updated_at": "Tue, 17 Dec 2019 17:46:45 -0000", "id": 2, "name": "Wildan", "age": 22, "sex": "Male"}]}
[2019-12-17 18:23:55,628] {/home/alta-18/Documents/Alterra/FlaskPractice/.flaskblog_venv/lib/python3.6/site-packages/flask/app.py:1891} ERROR - Exception on /user/1 [PUT]
Traceback (most recent call last):
  File "/home/alta-18/Documents/Alterra/FlaskPractice/.flaskblog_venv/lib/python3.6/site-packages/flask/app.py", line 1949, in full_dispatch_request
    rv = self.dispatch_request()
  File "/home/alta-18/Documents/Alterra/FlaskPractice/.flaskblog_venv/lib/python3.6/site-packages/flask/app.py", line 1935, in dispatch_request
    return self.view_functions[rule.endpoint](**req.view_args)
  File "/home/alta-18/Documents/Alterra/FlaskPractice/.flaskblog_venv/lib/python3.6/site-packages/flask_restful/__init__.py", line 458, in wrapper
    resp = resource(*args, **kwargs)
  File "/home/alta-18/Documents/Alterra/FlaskPractice/.flaskblog_venv/lib/python3.6/site-packages/flask/views.py", line 89, in view
    return self.dispatch_request(*args, **kwargs)
  File "/home/alta-18/Documents/Alterra/FlaskPractice/.flaskblog_venv/lib/python3.6/site-packages/flask_restful/__init__.py", line 573, in dispatch_request
    resp = meth(*args, **kwargs)
  File "/home/alta-18/Documents/Alterra/FlaskPractice/blueprints/user/resources.py", line 66, in put
    qry = Users.get(id)
AttributeError: type object 'Users' has no attribute 'get'
[2019-12-17 18:23:55,630] {/home/alta-18/Documents/Alterra/FlaskPractice/blueprints/__init__.py:43} ERROR - REQUEST_LOG	{"method": "PUT", "code": "500 INTERNAL SERVER ERROR", "request": {"name": "Wildan Firdaus", "age": 22, "sex": "Male"}, "response": {"message": "Internal Server Error"}}
[2019-12-17 18:24:31,674] {/home/alta-18/Documents/Alterra/FlaskPractice/.flaskblog_venv/lib/python3.6/site-packages/flask/app.py:1891} ERROR - Exception on /user/1 [PUT]
Traceback (most recent call last):
  File "/home/alta-18/Documents/Alterra/FlaskPractice/.flaskblog_venv/lib/python3.6/site-packages/flask/app.py", line 1949, in full_dispatch_request
    rv = self.dispatch_request()
  File "/home/alta-18/Documents/Alterra/FlaskPractice/.flaskblog_venv/lib/python3.6/site-packages/flask/app.py", line 1935, in dispatch_request
    return self.view_functions[rule.endpoint](**req.view_args)
  File "/home/alta-18/Documents/Alterra/FlaskPractice/.flaskblog_venv/lib/python3.6/site-packages/flask_restful/__init__.py", line 458, in wrapper
    resp = resource(*args, **kwargs)
  File "/home/alta-18/Documents/Alterra/FlaskPractice/.flaskblog_venv/lib/python3.6/site-packages/flask/views.py", line 89, in view
    return self.dispatch_request(*args, **kwargs)
  File "/home/alta-18/Documents/Alterra/FlaskPractice/.flaskblog_venv/lib/python3.6/site-packages/flask_restful/__init__.py", line 573, in dispatch_request
    resp = meth(*args, **kwargs)
  File "/home/alta-18/Documents/Alterra/FlaskPractice/blueprints/user/resources.py", line 67, in put
    if result is None:
NameError: name 'result' is not defined
[2019-12-17 18:24:31,676] {/home/alta-18/Documents/Alterra/FlaskPractice/blueprints/__init__.py:43} ERROR - REQUEST_LOG	{"method": "PUT", "code": "500 INTERNAL SERVER ERROR", "request": {"name": "Wildan Firdaus", "age": 22, "sex": "Male"}, "response": {"message": "Internal Server Error"}}
[2019-12-17 18:24:46,125] {/home/alta-18/Documents/Alterra/FlaskPractice/blueprints/__init__.py:36} INFO - REQUEST_LOG	{"method": "PUT", "code": "200 OK", "request": {"name": "Wildan Firdaus", "age": 22, "sex": "Male"}, "response": {"created_at": "Tue, 17 Dec 2019 17:45:04 -0000", "updated_at": null, "id": 1, "name": "Wildan Firdaus", "age": 22, "sex": "Male"}}
[2019-12-17 18:24:57,253] {/home/alta-18/Documents/Alterra/FlaskPractice/blueprints/__init__.py:36} INFO - REQUEST_LOG	{"method": "GET", "code": "200 OK", "request": {"name": "Wildan Firdaus", "age": 22, "sex": "Male"}, "response": [{"created_at": "Tue, 17 Dec 2019 17:45:04 -0000", "updated_at": null, "id": 1, "name": "Wildan", "age": 22, "sex": "Male"}, {"created_at": "Tue, 17 Dec 2019 17:46:45 -0000", "updated_at": "Tue, 17 Dec 2019 17:46:45 -0000", "id": 2, "name": "Wildan", "age": 22, "sex": "Male"}]}
[2019-12-17 18:25:17,039] {/home/alta-18/Documents/Alterra/FlaskPractice/blueprints/__init__.py:36} INFO - REQUEST_LOG	{"method": "PUT", "code": "200 OK", "request": {"name": "Wildanzzz", "age": 22, "sex": "Male"}, "response": {"created_at": "Tue, 17 Dec 2019 17:46:45 -0000", "updated_at": "Tue, 17 Dec 2019 17:46:45 -0000", "id": 2, "name": "Wildanzzz", "age": 22, "sex": "Male"}}
[2019-12-17 18:25:58,082] {/home/alta-18/Documents/Alterra/FlaskPractice/blueprints/__init__.py:36} INFO - REQUEST_LOG	{"method": "PUT", "code": "200 OK", "request": {"name": "Wildanzzz", "age": 22, "sex": "Male"}, "response": null}
[2019-12-17 18:26:04,233] {/home/alta-18/Documents/Alterra/FlaskPractice/blueprints/__init__.py:36} INFO - REQUEST_LOG	{"method": "GET", "code": "200 OK", "request": {"name": "Wildanzzz", "age": 22, "sex": "Male"}, "response": [{"created_at": "Tue, 17 Dec 2019 17:45:04 -0000", "updated_at": null, "id": 1, "name": "Wildan", "age": 22, "sex": "Male"}, {"created_at": "Tue, 17 Dec 2019 17:46:45 -0000", "updated_at": "Tue, 17 Dec 2019 17:46:45 -0000", "id": 2, "name": "Wildan", "age": 22, "sex": "Male"}]}
[2019-12-17 18:26:18,623] {/home/alta-18/Documents/Alterra/FlaskPractice/blueprints/__init__.py:36} INFO - REQUEST_LOG	{"method": "PUT", "code": "200 OK", "request": {"name": "Wildanzzz", "age": 22, "sex": "Male"}, "response": {"created_at": "Tue, 17 Dec 2019 17:45:04 -0000", "updated_at": "Tue, 17 Dec 2019 18:25:51 -0000", "id": 1, "name": "Wildanzzz", "age": 22, "sex": "Male"}}
[2019-12-17 18:26:28,945] {/home/alta-18/Documents/Alterra/FlaskPractice/blueprints/__init__.py:36} INFO - REQUEST_LOG	{"method": "GET", "code": "200 OK", "request": {"name": "Wildanzzz", "age": 22, "sex": "Male"}, "response": [{"created_at": "Tue, 17 Dec 2019 17:45:04 -0000", "updated_at": "Tue, 17 Dec 2019 18:25:51 -0000", "id": 1, "name": "Wildanzzz", "age": 22, "sex": "Male"}, {"created_at": "Tue, 17 Dec 2019 17:46:45 -0000", "updated_at": "Tue, 17 Dec 2019 17:46:45 -0000", "id": 2, "name": "Wildan", "age": 22, "sex": "Male"}]}
[2019-12-17 18:51:37,457] {/home/alta-18/Documents/Alterra/FlaskPractice/.flaskblog_venv/lib/python3.6/site-packages/flask/app.py:1891} ERROR - Exception on /user [GET]
Traceback (most recent call last):
  File "/home/alta-18/Documents/Alterra/FlaskPractice/.flaskblog_venv/lib/python3.6/site-packages/flask/app.py", line 1949, in full_dispatch_request
    rv = self.dispatch_request()
  File "/home/alta-18/Documents/Alterra/FlaskPractice/.flaskblog_venv/lib/python3.6/site-packages/flask/app.py", line 1935, in dispatch_request
    return self.view_functions[rule.endpoint](**req.view_args)
  File "/home/alta-18/Documents/Alterra/FlaskPractice/.flaskblog_venv/lib/python3.6/site-packages/flask_restful/__init__.py", line 458, in wrapper
    resp = resource(*args, **kwargs)
  File "/home/alta-18/Documents/Alterra/FlaskPractice/.flaskblog_venv/lib/python3.6/site-packages/flask/views.py", line 89, in view
    return self.dispatch_request(*args, **kwargs)
  File "/home/alta-18/Documents/Alterra/FlaskPractice/.flaskblog_venv/lib/python3.6/site-packages/flask_restful/__init__.py", line 573, in dispatch_request
    resp = meth(*args, **kwargs)
  File "/home/alta-18/Documents/Alterra/FlaskPractice/blueprints/user/resources.py", line 34, in get
    qry = qry.limit(args["rp"]).offset(offset)
UnboundLocalError: local variable 'qry' referenced before assignment
[2019-12-17 18:51:37,458] {/home/alta-18/Documents/Alterra/FlaskPractice/blueprints/__init__.py:43} ERROR - REQUEST_LOG	{"method": "GET", "code": "500 INTERNAL SERVER ERROR", "request": {"name": "Wildanzzz", "age": 22, "sex": "Male"}, "response": {"message": "Internal Server Error"}}
[2019-12-17 18:53:33,386] {/home/alta-18/Documents/Alterra/FlaskPractice/blueprints/__init__.py:36} INFO - REQUEST_LOG	{"method": "GET", "code": "200 OK", "request": {"name": "Wildanzzz", "age": 22, "sex": "Male"}, "response": []}
[2019-12-17 18:53:55,658] {/home/alta-18/Documents/Alterra/FlaskPractice/blueprints/__init__.py:43} ERROR - REQUEST_LOG	{"method": "PUT", "code": "400 BAD REQUEST", "request": {}, "response": {"message": "The browser (or proxy) sent a request that this server could not understand."}}
[2019-12-17 18:55:19,472] {/home/alta-18/Documents/Alterra/FlaskPractice/.flaskblog_venv/lib/python3.6/site-packages/flask/app.py:1891} ERROR - Exception on /user/1 [PUT]
Traceback (most recent call last):
  File "/home/alta-18/Documents/Alterra/FlaskPractice/.flaskblog_venv/lib/python3.6/site-packages/flask/app.py", line 1949, in full_dispatch_request
    rv = self.dispatch_request()
  File "/home/alta-18/Documents/Alterra/FlaskPractice/.flaskblog_venv/lib/python3.6/site-packages/flask/app.py", line 1935, in dispatch_request
    return self.view_functions[rule.endpoint](**req.view_args)
  File "/home/alta-18/Documents/Alterra/FlaskPractice/.flaskblog_venv/lib/python3.6/site-packages/flask_restful/__init__.py", line 458, in wrapper
    resp = resource(*args, **kwargs)
  File "/home/alta-18/Documents/Alterra/FlaskPractice/.flaskblog_venv/lib/python3.6/site-packages/flask/views.py", line 89, in view
    return self.dispatch_request(*args, **kwargs)
  File "/home/alta-18/Documents/Alterra/FlaskPractice/.flaskblog_venv/lib/python3.6/site-packages/flask_restful/__init__.py", line 573, in dispatch_request
    resp = meth(*args, **kwargs)
  File "/home/alta-18/Documents/Alterra/FlaskPractice/blueprints/user/resources.py", line 66, in put
    qry = qry.get(id)
  File "/home/alta-18/Documents/Alterra/FlaskPractice/.flaskblog_venv/lib/python3.6/site-packages/sqlalchemy/orm/query.py", line 982, in get
    return self._get_impl(ident, loading.load_on_pk_identity)
  File "/home/alta-18/Documents/Alterra/FlaskPractice/.flaskblog_venv/lib/python3.6/site-packages/sqlalchemy/orm/query.py", line 1094, in _get_impl
    return db_load_fn(self, primary_key_identity)
  File "/home/alta-18/Documents/Alterra/FlaskPractice/.flaskblog_venv/lib/python3.6/site-packages/sqlalchemy/orm/loading.py", line 221, in load_on_pk_identity
    q._get_condition()
  File "/home/alta-18/Documents/Alterra/FlaskPractice/.flaskblog_venv/lib/python3.6/site-packages/sqlalchemy/orm/query.py", line 430, in _get_condition
    "get", order_by=False, distinct=False
  File "/home/alta-18/Documents/Alterra/FlaskPractice/.flaskblog_venv/lib/python3.6/site-packages/sqlalchemy/orm/query.py", line 455, in _no_criterion_condition
    self._no_criterion_assertion(meth, order_by, distinct)
  File "/home/alta-18/Documents/Alterra/FlaskPractice/.flaskblog_venv/lib/python3.6/site-packages/sqlalchemy/orm/query.py", line 451, in _no_criterion_assertion
    "Query with existing criterion. " % meth
sqlalchemy.exc.InvalidRequestError: Query.get() being called on a Query with existing criterion. 
[2019-12-17 18:55:19,474] {/home/alta-18/Documents/Alterra/FlaskPractice/blueprints/__init__.py:43} ERROR - REQUEST_LOG	{"method": "PUT", "code": "500 INTERNAL SERVER ERROR", "request": {"name": "Wildanzzz", "age": 22, "sex": "Male", "deleted_status": 0}, "response": {"message": "Internal Server Error"}}
[2019-12-17 18:55:33,475] {/home/alta-18/Documents/Alterra/FlaskPractice/.flaskblog_venv/lib/python3.6/site-packages/flask/app.py:1891} ERROR - Exception on /user/1 [PUT]
Traceback (most recent call last):
  File "/home/alta-18/Documents/Alterra/FlaskPractice/.flaskblog_venv/lib/python3.6/site-packages/flask/app.py", line 1949, in full_dispatch_request
    rv = self.dispatch_request()
  File "/home/alta-18/Documents/Alterra/FlaskPractice/.flaskblog_venv/lib/python3.6/site-packages/flask/app.py", line 1935, in dispatch_request
    return self.view_functions[rule.endpoint](**req.view_args)
  File "/home/alta-18/Documents/Alterra/FlaskPractice/.flaskblog_venv/lib/python3.6/site-packages/flask_restful/__init__.py", line 458, in wrapper
    resp = resource(*args, **kwargs)
  File "/home/alta-18/Documents/Alterra/FlaskPractice/.flaskblog_venv/lib/python3.6/site-packages/flask/views.py", line 89, in view
    return self.dispatch_request(*args, **kwargs)
  File "/home/alta-18/Documents/Alterra/FlaskPractice/.flaskblog_venv/lib/python3.6/site-packages/flask_restful/__init__.py", line 573, in dispatch_request
    resp = meth(*args, **kwargs)
  File "/home/alta-18/Documents/Alterra/FlaskPractice/blueprints/user/resources.py", line 66, in put
    qry = qry.get(id)
  File "/home/alta-18/Documents/Alterra/FlaskPractice/.flaskblog_venv/lib/python3.6/site-packages/sqlalchemy/orm/query.py", line 982, in get
    return self._get_impl(ident, loading.load_on_pk_identity)
  File "/home/alta-18/Documents/Alterra/FlaskPractice/.flaskblog_venv/lib/python3.6/site-packages/sqlalchemy/orm/query.py", line 1094, in _get_impl
    return db_load_fn(self, primary_key_identity)
  File "/home/alta-18/Documents/Alterra/FlaskPractice/.flaskblog_venv/lib/python3.6/site-packages/sqlalchemy/orm/loading.py", line 221, in load_on_pk_identity
    q._get_condition()
  File "/home/alta-18/Documents/Alterra/FlaskPractice/.flaskblog_venv/lib/python3.6/site-packages/sqlalchemy/orm/query.py", line 430, in _get_condition
    "get", order_by=False, distinct=False
  File "/home/alta-18/Documents/Alterra/FlaskPractice/.flaskblog_venv/lib/python3.6/site-packages/sqlalchemy/orm/query.py", line 455, in _no_criterion_condition
    self._no_criterion_assertion(meth, order_by, distinct)
  File "/home/alta-18/Documents/Alterra/FlaskPractice/.flaskblog_venv/lib/python3.6/site-packages/sqlalchemy/orm/query.py", line 451, in _no_criterion_assertion
    "Query with existing criterion. " % meth
sqlalchemy.exc.InvalidRequestError: Query.get() being called on a Query with existing criterion. 
[2019-12-17 18:55:33,477] {/home/alta-18/Documents/Alterra/FlaskPractice/blueprints/__init__.py:43} ERROR - REQUEST_LOG	{"method": "PUT", "code": "500 INTERNAL SERVER ERROR", "request": {"name": "Wildanzzz", "age": 22, "sex": "Male"}, "response": {"message": "Internal Server Error"}}
[2019-12-17 18:56:43,285] {/home/alta-18/Documents/Alterra/FlaskPractice/.flaskblog_venv/lib/python3.6/site-packages/flask/app.py:1891} ERROR - Exception on /user/1 [POST]
Traceback (most recent call last):
  File "/home/alta-18/Documents/Alterra/FlaskPractice/.flaskblog_venv/lib/python3.6/site-packages/flask/app.py", line 1949, in full_dispatch_request
    rv = self.dispatch_request()
  File "/home/alta-18/Documents/Alterra/FlaskPractice/.flaskblog_venv/lib/python3.6/site-packages/flask/app.py", line 1935, in dispatch_request
    return self.view_functions[rule.endpoint](**req.view_args)
  File "/home/alta-18/Documents/Alterra/FlaskPractice/.flaskblog_venv/lib/python3.6/site-packages/flask_restful/__init__.py", line 458, in wrapper
    resp = resource(*args, **kwargs)
  File "/home/alta-18/Documents/Alterra/FlaskPractice/.flaskblog_venv/lib/python3.6/site-packages/flask/views.py", line 89, in view
    return self.dispatch_request(*args, **kwargs)
  File "/home/alta-18/Documents/Alterra/FlaskPractice/.flaskblog_venv/lib/python3.6/site-packages/flask_restful/__init__.py", line 573, in dispatch_request
    resp = meth(*args, **kwargs)
TypeError: post() got an unexpected keyword argument 'id'
[2019-12-17 18:56:43,288] {/home/alta-18/Documents/Alterra/FlaskPractice/blueprints/__init__.py:43} ERROR - REQUEST_LOG	{"method": "POST", "code": "500 INTERNAL SERVER ERROR", "request": {"name": "Wildanzzz", "age": 22, "sex": "Male"}, "response": {"message": "Internal Server Error"}}
[2019-12-17 18:56:58,099] {/home/alta-18/Documents/Alterra/FlaskPractice/blueprints/__init__.py:36} INFO - REQUEST_LOG	{"method": "POST", "code": "200 OK", "request": {"name": "Wildanzzz", "age": 22, "sex": "Male"}, "response": {"created_at": "Tue, 17 Dec 2019 18:56:42 -0000", "updated_at": "Tue, 17 Dec 2019 18:56:42 -0000", "id": 1, "name": "Wildanzzz", "age": 22, "sex": "Male"}}
[2019-12-17 18:57:20,629] {/home/alta-18/Documents/Alterra/FlaskPractice/blueprints/__init__.py:36} INFO - REQUEST_LOG	{"method": "POST", "code": "200 OK", "request": {"name": "Wildan", "age": 22, "sex": "Male"}, "response": {"created_at": "Tue, 17 Dec 2019 18:56:42 -0000", "updated_at": "Tue, 17 Dec 2019 18:56:42 -0000", "id": 2, "name": "Wildan", "age": 22, "sex": "Male"}}
[2019-12-17 18:57:29,550] {/home/alta-18/Documents/Alterra/FlaskPractice/blueprints/__init__.py:36} INFO - REQUEST_LOG	{"method": "GET", "code": "200 OK", "request": {"name": "Wildan", "age": 22, "sex": "Male"}, "response": [{"created_at": "Tue, 17 Dec 2019 18:56:42 -0000", "updated_at": "Tue, 17 Dec 2019 18:56:42 -0000", "id": 1, "name": "Wildanzzz", "age": 22, "sex": "Male"}, {"created_at": "Tue, 17 Dec 2019 18:56:42 -0000", "updated_at": "Tue, 17 Dec 2019 18:56:42 -0000", "id": 2, "name": "Wildan", "age": 22, "sex": "Male"}]}
[2019-12-17 18:57:37,792] {/home/alta-18/Documents/Alterra/FlaskPractice/.flaskblog_venv/lib/python3.6/site-packages/flask/app.py:1891} ERROR - Exception on /user/1 [GET]
Traceback (most recent call last):
  File "/home/alta-18/Documents/Alterra/FlaskPractice/.flaskblog_venv/lib/python3.6/site-packages/flask/app.py", line 1949, in full_dispatch_request
    rv = self.dispatch_request()
  File "/home/alta-18/Documents/Alterra/FlaskPractice/.flaskblog_venv/lib/python3.6/site-packages/flask/app.py", line 1935, in dispatch_request
    return self.view_functions[rule.endpoint](**req.view_args)
  File "/home/alta-18/Documents/Alterra/FlaskPractice/.flaskblog_venv/lib/python3.6/site-packages/flask_restful/__init__.py", line 458, in wrapper
    resp = resource(*args, **kwargs)
  File "/home/alta-18/Documents/Alterra/FlaskPractice/.flaskblog_venv/lib/python3.6/site-packages/flask/views.py", line 89, in view
    return self.dispatch_request(*args, **kwargs)
  File "/home/alta-18/Documents/Alterra/FlaskPractice/.flaskblog_venv/lib/python3.6/site-packages/flask_restful/__init__.py", line 573, in dispatch_request
    resp = meth(*args, **kwargs)
  File "/home/alta-18/Documents/Alterra/FlaskPractice/blueprints/user/resources.py", line 38, in get
    qry = qry.get(id)
  File "/home/alta-18/Documents/Alterra/FlaskPractice/.flaskblog_venv/lib/python3.6/site-packages/sqlalchemy/orm/query.py", line 982, in get
    return self._get_impl(ident, loading.load_on_pk_identity)
  File "/home/alta-18/Documents/Alterra/FlaskPractice/.flaskblog_venv/lib/python3.6/site-packages/sqlalchemy/orm/query.py", line 1094, in _get_impl
    return db_load_fn(self, primary_key_identity)
  File "/home/alta-18/Documents/Alterra/FlaskPractice/.flaskblog_venv/lib/python3.6/site-packages/sqlalchemy/orm/loading.py", line 221, in load_on_pk_identity
    q._get_condition()
  File "/home/alta-18/Documents/Alterra/FlaskPractice/.flaskblog_venv/lib/python3.6/site-packages/sqlalchemy/orm/query.py", line 430, in _get_condition
    "get", order_by=False, distinct=False
  File "/home/alta-18/Documents/Alterra/FlaskPractice/.flaskblog_venv/lib/python3.6/site-packages/sqlalchemy/orm/query.py", line 455, in _no_criterion_condition
    self._no_criterion_assertion(meth, order_by, distinct)
  File "/home/alta-18/Documents/Alterra/FlaskPractice/.flaskblog_venv/lib/python3.6/site-packages/sqlalchemy/orm/query.py", line 451, in _no_criterion_assertion
    "Query with existing criterion. " % meth
sqlalchemy.exc.InvalidRequestError: Query.get() being called on a Query with existing criterion. 
[2019-12-17 18:57:37,795] {/home/alta-18/Documents/Alterra/FlaskPractice/blueprints/__init__.py:43} ERROR - REQUEST_LOG	{"method": "GET", "code": "500 INTERNAL SERVER ERROR", "request": {"name": "Wildan", "age": 22, "sex": "Male"}, "response": {"message": "Internal Server Error"}}
